Workbook

Sheet Para. setting
A1: 1 | B1: 1 | C1: 1 | D1: 1 | E1: 1 | F1: 1 | M1: 1 | N1: 2 | O1: 3 | P1: 4 | Q1: 5
A2: 1 | B2: 2 | C2: 3 | D2: 4 | E2: 5 | F2: 2 | L2: the population size factor | M2: 1 | N2: 1.5 | O2: 2 | P2: 2.5 | Q2: 3
A3: 1 | B3: 3 | C3: 5 | D3: 2 | E3: 4 | F3: 3 | L3: the scale factor | M3: 1 | N3: 1.2 | O3: 1.4 | P3: 1.6 | Q3: 1.8
A4: 1 | B4: 4 | C4: 2 | D4: 5 | E4: 3 | F4: 4 | L4: the weight factor | M4: 0.5 | N4: 0.6 | O4: 0.7 | P4: 0.8 | Q4: 0.9
A5: 1 | B5: 5 | C5: 4 | D5: 3 | E5: 2 | F5: 5 | L5: the biases rate | M5: 0.7 | N5: 0.75 | O5: 0.8 | P5: 0.85 | Q5: 0.9
A6: 2 | B6: 1 | C6: 5 | D6: 4 | E6: 3 | F6: 5 | L6: the immigration rate | M6: 0.05 | N6: 0.1 | O6: 0.15 | P6: 0.2 | Q6: 0.25
A7: 2 | B7: 2 | C7: 2 | D7: 2 | E7: 2 | F7: 1 | L7: the improvement rate | M7: 0.02 | N7: 0.04 | O7: 0.06 | P7: 0.08 | Q7: 0.1
A8: 2 | B8: 3 | C8: 4 | D8: 5 | E8: 1 | F8: 2
A9: 2 | B9: 4 | C9: 1 | D9: 3 | E9: 5 | F9: 3
A10: 2 | B10: 5 | C10: 3 | D10: 1 | E10: 4 | F10: 4
A11: 3 | B11: 1 | C11: 4 | D11: 2 | E11: 5 | F11: 4 | L11: 1 | M11: =HLOOKUP(A1,$M$1:$Q$7,2) -> 1 | N11: =HLOOKUP(B1,$M$1:$Q$7,3) -> 1 | O11: =HLOOKUP(C1,$M$1:$Q$7,4) -> 0.5 | P11: =HLOOKUP(D1,$M$1:$Q$7,5) -> 0.7 | Q11: =HLOOKUP(E1,$M$1:$Q$7,6) -> 0.05 | R11: =HLOOKUP(F1,$M$1:$Q$7,7) -> 0.02 | V11: =M11&" "&N11&" "&O11&" "&P11&" "&Q11&" "&R11&" " -> 1 1 0.5 0.7 0.05 0.02 | Z11: 1 | AA11: 1 | AB11: 0.5 | AC11: 0.7 | AD11: 0.05 | AE11: 0.02
A12: 3 | B12: 2 | C12: 1 | D12: 5 | E12: 4 | F12: 5 | L12: 2 | M12: =HLOOKUP(A2,$M$1:$Q$7,2) -> 1 | N12: =HLOOKUP(B2,$M$1:$Q$7,3) -> 1.2 | O12: =HLOOKUP(C2,$M$1:$Q$7,4) -> 0.7 | P12: =HLOOKUP(D2,$M$1:$Q$7,5) -> 0.85 | Q12: =HLOOKUP(E2,$M$1:$Q$7,6) -> 0.25 | R12: =HLOOKUP(F2,$M$1:$Q$7,7) -> 0.04 | V12: =M12&" "&N12&" "&O12&" "&P12&" "&Q12&" "&R12&" " -> 1 1.2 0.7 0.85 0.25 0.04 | Z12: 1 | AA12: 1.2 | AB12: 0.7 | AC12: 0.85 | AD12: 0.25 | AE12: 0.04
A13: 3 | B13: 3 | C13: 3 | D13: 3 | E13: 3 | F13: 1 | L13: 3 | M13: =HLOOKUP(A3,$M$1:$Q$7,2) -> 1 | N13: =HLOOKUP(B3,$M$1:$Q$7,3) -> 1.4 | O13: =HLOOKUP(C3,$M$1:$Q$7,4) -> 0.9 | P13: =HLOOKUP(D3,$M$1:$Q$7,5) -> 0.75 | Q13: =HLOOKUP(E3,$M$1:$Q$7,6) -> 0.2 | R13: =HLOOKUP(F3,$M$1:$Q$7,7) -> 0.06 | V13: =M13&" "&N13&" "&O13&" "&P13&" "&Q13&" "&R13&" " -> 1 1.4 0.9 0.75 0.2 0.06 | Z13: 1 | AA13: 1.4 | AB13: 0.9 | AC13: 0.75 | AD13: 0.2 | AE13: 0.06
A14: 3 | B14: 4 | C14: 5 | D14: 1 | E14: 2 | F14: 2 | L14: 4 | M14: =HLOOKUP(A4,$M$1:$Q$7,2) -> 1 | N14: =HLOOKUP(B4,$M$1:$Q$7,3) -> 1.6 | O14: =HLOOKUP(C4,$M$1:$Q$7,4) -> 0.6 | P14: =HLOOKUP(D4,$M$1:$Q$7,5) -> 0.9 | Q14: =HLOOKUP(E4,$M$1:$Q$7,6) -> 0.15 | R14: =HLOOKUP(F4,$M$1:$Q$7,7) -> 0.08 | V14: =M14&" "&N14&" "&O14&" "&P14&" "&Q14&" "&R14&" " -> 1 1.6 0.6 0.9 0.15 0.08 | Z14: 1 | AA14: 1.6 | AB14: 0.6 | AC14: 0.9 | AD14: 0.15 | AE14: 0.08
A15: 3 | B15: 5 | C15: 2 | D15: 4 | E15: 1 | F15: 3 | L15: 5 | M15: =HLOOKUP(A5,$M$1:$Q$7,2) -> 1 | N15: =HLOOKUP(B5,$M$1:$Q$7,3) -> 1.8 | O15: =HLOOKUP(C5,$M$1:$Q$7,4) -> 0.8 | P15: =HLOOKUP(D5,$M$1:$Q$7,5) -> 0.8 | Q15: =HLOOKUP(E5,$M$1:$Q$7,6) -> 0.1 | R15: =HLOOKUP(F5,$M$1:$Q$7,7) -> 0.1 | V15: =M15&" "&N15&" "&O15&" "&P15&" "&Q15&" "&R15&" " -> 1 1.8 0.8 0.8 0.1 0.1 | Z15: 1 | AA15: 1.8 | AB15: 0.8 | AC15: 0.8 | AD15: 0.1 | AE15: 0.1
A16: 4 | B16: 1 | C16: 3 | D16: 5 | E16: 2 | F16: 3 | L16: 6 | M16: =HLOOKUP(A6,$M$1:$Q$7,2) -> 1.5 | N16: =HLOOKUP(B6,$M$1:$Q$7,3) -> 1 | O16: =HLOOKUP(C6,$M$1:$Q$7,4) -> 0.9 | P16: =HLOOKUP(D6,$M$1:$Q$7,5) -> 0.85 | Q16: =HLOOKUP(E6,$M$1:$Q$7,6) -> 0.15 | R16: =HLOOKUP(F6,$M$1:$Q$7,7) -> 0.1 | V16: =M16&" "&N16&" "&O16&" "&P16&" "&Q16&" "&R16&" " -> 1.5 1 0.9 0.85 0.15 0.1 | Z16: 1.5 | AA16: 1 | AB16: 0.9 | AC16: 0.85 | AD16: 0.15 | AE16: 0.1
A17: 4 | B17: 2 | C17: 5 | D17: 3 | E17: 1 | F17: 4 | L17: 7 | M17: =HLOOKUP(A7,$M$1:$Q$7,2) -> 1.5 | N17: =HLOOKUP(B7,$M$1:$Q$7,3) -> 1.2 | O17: =HLOOKUP(C7,$M$1:$Q$7,4) -> 0.6 | P17: =HLOOKUP(D7,$M$1:$Q$7,5) -> 0.75 | Q17: =HLOOKUP(E7,$M$1:$Q$7,6) -> 0.1 | R17: =HLOOKUP(F7,$M$1:$Q$7,7) -> 0.02 | V17: =M17&" "&N17&" "&O17&" "&P17&" "&Q17&" "&R17&" " -> 1.5 1.2 0.6 0.75 0.1 0.02 | Z17: 1.5 | AA17: 1.2 | AB17: 0.6 | AC17: 0.75 | AD17: 0.1 | AE17: 0.02
A18: 4 | B18: 3 | C18: 2 | D18: 1 | E18: 5 | F18: 5 | L18: 8 | M18: =HLOOKUP(A8,$M$1:$Q$7,2) -> 1.5 | N18: =HLOOKUP(B8,$M$1:$Q$7,3) -> 1.4 | O18: =HLOOKUP(C8,$M$1:$Q$7,4) -> 0.8 | P18: =HLOOKUP(D8,$M$1:$Q$7,5) -> 0.9 | Q18: =HLOOKUP(E8,$M$1:$Q$7,6) -> 0.05 | R18: =HLOOKUP(F8,$M$1:$Q$7,7) -> 0.04 | V18: =M18&" "&N18&" "&O18&" "&P18&" "&Q18&" "&R18&" " -> 1.5 1.4 0.8 0.9 0.05 0.04 | Z18: 1.5 | AA18: 1.4 | AB18: 0.8 | AC18: 0.9 | AD18: 0.05 | AE18: 0.04
A19: 4 | B19: 4 | C19: 4 | D19: 4 | E19: 4 | F19: 1 | L19: 9 | M19: =HLOOKUP(A9,$M$1:$Q$7,2) -> 1.5 | N19: =HLOOKUP(B9,$M$1:$Q$7,3) -> 1.6 | O19: =HLOOKUP(C9,$M$1:$Q$7,4) -> 0.5 | P19: =HLOOKUP(D9,$M$1:$Q$7,5) -> 0.8 | Q19: =HLOOKUP(E9,$M$1:$Q$7,6) -> 0.25 | R19: =HLOOKUP(F9,$M$1:$Q$7,7) -> 0.06 | V19: =M19&" "&N19&" "&O19&" "&P19&" "&Q19&" "&R19&" " -> 1.5 1.6 0.5 0.8 0.25 0.06 | Z19: 1.5 | AA19: 1.6 | AB19: 0.5 | AC19: 0.8 | AD19: 0.25 | AE19: 0.06
A20: 4 | B20: 5 | C20: 1 | D20: 2 | E20: 3 | F20: 2 | L20: 10 | M20: =HLOOKUP(A10,$M$1:$Q$7,2) -> 1.5 | N20: =HLOOKUP(B10,$M$1:$Q$7,3) -> 1.8 | O20: =HLOOKUP(C10,$M$1:$Q$7,4) -> 0.7 | P20: =HLOOKUP(D10,$M$1:$Q$7,5) -> 0.7 | Q20: =HLOOKUP(E10,$M$1:$Q$7,6) -> 0.2 | R20: =HLOOKUP(F10,$M$1:$Q$7,7) -> 0.08 | V20: =M20&" "&N20&" "&O20&" "&P20&" "&Q20&" "&R20&" " -> 1.5 1.8 0.7 0.7 0.2 0.08 | Z20: 1.5 | AA20: 1.8 | AB20: 0.7 | AC20: 0.7 | AD20: 0.2 | AE20: 0.08
A21: 5 | B21: 1 | C21: 2 | D21: 3 | E21: 4 | F21: 2 | L21: 11 | M21: =HLOOKUP(A11,$M$1:$Q$7,2) -> 2 | N21: =HLOOKUP(B11,$M$1:$Q$7,3) -> 1 | O21: =HLOOKUP(C11,$M$1:$Q$7,4) -> 0.8 | P21: =HLOOKUP(D11,$M$1:$Q$7,5) -> 0.75 | Q21: =HLOOKUP(E11,$M$1:$Q$7,6) -> 0.25 | R21: =HLOOKUP(F11,$M$1:$Q$7,7) -> 0.08 | V21: =M21&" "&N21&" "&O21&" "&P21&" "&Q21&" "&R21&" " -> 2 1 0.8 0.75 0.25 0.08 | Z21: 2 | AA21: 1 | AB21: 0.8 | AC21: 0.75 | AD21: 0.25 | AE21: 0.08
A22: 5 | B22: 2 | C22: 4 | D22: 1 | E22: 3 | F22: 3 | L22: 12 | M22: =HLOOKUP(A12,$M$1:$Q$7,2) -> 2 | N22: =HLOOKUP(B12,$M$1:$Q$7,3) -> 1.2 | O22: =HLOOKUP(C12,$M$1:$Q$7,4) -> 0.5 | P22: =HLOOKUP(D12,$M$1:$Q$7,5) -> 0.9 | Q22: =HLOOKUP(E12,$M$1:$Q$7,6) -> 0.2 | R22: =HLOOKUP(F12,$M$1:$Q$7,7) -> 0.1 | V22: =M22&" "&N22&" "&O22&" "&P22&" "&Q22&" "&R22&" " -> 2 1.2 0.5 0.9 0.2 0.1 | Z22: 2 | AA22: 1.2 | AB22: 0.5 | AC22: 0.9 | AD22: 0.2 | AE22: 0.1
... A25: 5 | B25: 5 | C25: 5 | D25: 5 | E25: 5 | F25: 1 | L25: 15 | M25: =HLOOKUP(A15,$M$1:$Q$7,2) -> 2 | N25: =HLOOKUP(B15,$M$1:$Q$7,3) -> 1.8 | O25: =HLOOKUP(C15,$M$1:$Q$7,4) -> 0.6 | P25: =HLOOKUP(D15,$M$1:$Q$7,5) -> 0.85 | Q25: =HLOOKUP(E15,$M$1:$Q$7,6) -> 0.05 | R25: =HLOOKUP(F15,$M$1:$Q$7,7) -> 0.06 | V25: =M25&" "&N25&" "&O25&" "&P25&" "&Q25&" "&R25&" " -> 2 1.8 0.6 0.85 0.05 0.06 | Z25: 2 | AA25: 1.8 | AB25: 0.6 | AC25: 0.85 | AD25: 0.05 | AE25: 0.06
L26: 16 | M26: =HLOOKUP(A16,$M$1:$Q$7,2) -> 2.5 | N26: =HLOOKUP(B16,$M$1:$Q$7,3) -> 1 | O26: =HLOOKUP(C16,$M$1:$Q$7,4) -> 0.7 | P26: =HLOOKUP(D16,$M$1:$Q$7,5) -> 0.9 | Q26: =HLOOKUP(E16,$M$1:$Q$7,6) -> 0.1 | R26: =HLOOKUP(F16,$M$1:$Q$7,7) -> 0.06 | V26: =M26&" "&N26&" "&O26&" "&P26&" "&Q26&" "&R26&" " -> 2.5 1 0.7 0.9 0.1 0.06 | Z26: 2.5 | AA26: 1 | AB26: 0.7 | AC26: 0.9 | AD26: 0.1 | AE26: 0.06
L27: 17 | M27: =HLOOKUP(A17,$M$1:$Q$7,2) -> 2.5 | N27: =HLOOKUP(B17,$M$1:$Q$7,3) -> 1.2 | O27: =HLOOKUP(C17,$M$1:$Q$7,4) -> 0.9 | P27: =HLOOKUP(D17,$M$1:$Q$7,5) -> 0.8 | Q27: =HLOOKUP(E17,$M$1:$Q$7,6) -> 0.05 | R27: =HLOOKUP(F17,$M$1:$Q$7,7) -> 0.08 | V27: =M27&" "&N27&" "&O27&" "&P27&" "&Q27&" "&R27&" " -> 2.5 1.2 0.9 0.8 0.05 0.08 | Z27: 2.5 | AA27: 1.2 | AB27: 0.9 | AC27: 0.8 | AD27: 0.05 | AE27: 0.08
L28: 18 | M28: =HLOOKUP(A18,$M$1:$Q$7,2) -> 2.5 | N28: =HLOOKUP(B18,$M$1:$Q$7,3) -> 1.4 | O28: =HLOOKUP(C18,$M$1:$Q$7,4) -> 0.6 | P28: =HLOOKUP(D18,$M$1:$Q$7,5) -> 0.7 | Q28: =HLOOKUP(E18,$M$1:$Q$7,6) -> 0.25 | R28: =HLOOKUP(F18,$M$1:$Q$7,7) -> 0.1 | V28: =M28&" "&N28&" "&O28&" "&P28&" "&Q28&" "&R28&" " -> 2.5 1.4 0.6 0.7 0.25 0.1 | Z28: 2.5 | AA28: 1.4 | AB28: 0.6 | AC28: 0.7 | AD28: 0.25 | AE28: 0.1
L29: 19 | M29: =HLOOKUP(A19,$M$1:$Q$7,2) -> 2.5 | N29: =HLOOKUP(B19,$M$1:$Q$7,3) -> 1.6 | O29: =HLOOKUP(C19,$M$1:$Q$7,4) -> 0.8 | P29: =HLOOKUP(D19,$M$1:$Q$7,5) -> 0.85 | Q29: =HLOOKUP(E19,$M$1:$Q$7,6) -> 0.2 | R29: =HLOOKUP(F19,$M$1:$Q$7,7) -> 0.02 | V29: =M29&" "&N29&" "&O29&" "&P29&" "&Q29&" "&R29&" " -> 2.5 1.6 0.8 0.85 0.2 0.02 | Z29: 2.5 | AA29: 1.6 | AB29: 0.8 | AC29: 0.85 | AD29: 0.2 | AE29: 0.02
L30: 20 | M30: =HLOOKUP(A20,$M$1:$Q$7,2) -> 2.5 | N30: =HLOOKUP(B20,$M$1:$Q$7,3) -> 1.8 | O30: =HLOOKUP(C20,$M$1:$Q$7,4) -> 0.5 | P30: =HLOOKUP(D20,$M$1:$Q$7,5) -> 0.75 | Q30: =HLOOKUP(E20,$M$1:$Q$7,6) -> 0.15 | R30: =HLOOKUP(F20,$M$1:$Q$7,7) -> 0.04 | V30: =M30&" "&N30&" "&O30&" "&P30&" "&Q30&" "&R30&" " -> 2.5 1.8 0.5 0.75 0.15 0.04 | Z30: 2.5 | AA30: 1.8 | AB30: 0.5 | AC30: 0.75 | AD30: 0.15 | AE30: 0.04
L31: 21 | M31: =HLOOKUP(A21,$M$1:$Q$7,2) -> 3 | N31: =HLOOKUP(B21,$M$1:$Q$7,3) -> 1 | O31: =HLOOKUP(C21,$M$1:$Q$7,4) -> 0.6 | P31: =HLOOKUP(D21,$M$1:$Q$7,5) -> 0.8 | Q31: =HLOOKUP(E21,$M$1:$Q$7,6) -> 0.2 | R31: =HLOOKUP(F21,$M$1:$Q$7,7) -> 0.04 | V31: =M31&" "&N31&" "&O31&" "&P31&" "&Q31&" "&R31&" " -> 3 1 0.6 0.8 0.2 0.04 | Z31: 3 | AA31: 1 | AB31: 0.6 | AC31: 0.8 | AD31: 0.2 | AE31: 0.04
L32: 22 | M32: =HLOOKUP(A22,$M$1:$Q$7,2) -> 3 | N32: =HLOOKUP(B22,$M$1:$Q$7,3) -> 1.2 | O32: =HLOOKUP(C22,$M$1:$Q$7,4) -> 0.8 | P32: =HLOOKUP(D22,$M$1:$Q$7,5) -> 0.7 | Q32: =HLOOKUP(E22,$M$1:$Q$7,6) -> 0.15 | R32: =HLOOKUP(F22,$M$1:$Q$7,7) -> 0.06 | V32: =M32&" "&N32&" "&O32&" "&P32&" "&Q32&" "&R32&" " -> 3 1.2 0.8 0.7 0.15 0.06 | Z32: 3 | AA32: 1.2 | AB32: 0.8 | AC32: 0.7 | AD32: 0.15 | AE32: 0.06
L33: 23 | M33: =HLOOKUP(A23,$M$1:$Q$7,2) -> 3 | N33: =HLOOKUP(B23,$M$1:$Q$7,3) -> 1.4 | O33: =HLOOKUP(C23,$M$1:$Q$7,4) -> 0.5 | P33: =HLOOKUP(D23,$M$1:$Q$7,5) -> 0.85 | Q33: =HLOOKUP(E23,$M$1:$Q$7,6) -> 0.1 | R33: =HLOOKUP(F23,$M$1:$Q$7,7) -> 0.08 | V33: =M33&" "&N33&" "&O33&" "&P33&" "&Q33&" "&R33&" " -> 3 1.4 0.5 0.85 0.1 0.08 | Z33: 3 | AA33: 1.4 | AB33: 0.5 | AC33: 0.85 | AD33: 0.1 | AE33: 0.08
L34: 24 | M34: =HLOOKUP(A24,$M$1:$Q$7,2) -> 3 | N34: =HLOOKUP(B24,$M$1:$Q$7,3) -> 1.6 | O34: =HLOOKUP(C24,$M$1:$Q$7,4) -> 0.7 | P34: =HLOOKUP(D24,$M$1:$Q$7,5) -> 0.75 | Q34: =HLOOKUP(E24,$M$1:$Q$7,6) -> 0.05 | R34: =HLOOKUP(F24,$M$1:$Q$7,7) -> 0.1 | V34: =M34&" "&N34&" "&O34&" "&P34&" "&Q34&" "&R34&" " -> 3 1.6 0.7 0.75 0.05 0.1 | Z34: 3 | AA34: 1.6 | AB34: 0.7 | AC34: 0.75 | AD34: 0.05 | AE34: 0.1
L35: 25 | M35: =HLOOKUP(A25,$M$1:$Q$7,2) -> 3 | N35: =HLOOKUP(B25,$M$1:$Q$7,3) -> 1.8 | O35: =HLOOKUP(C25,$M$1:$Q$7,4) -> 0.9 | P35: =HLOOKUP(D25,$M$1:$Q$7,5) -> 0.9 | Q35: =HLOOKUP(E25,$M$1:$Q$7,6) -> 0.25 | R35: =HLOOKUP(F25,$M$1:$Q$7,7) -> 0.02 | V35: =M35&" "&N35&" "&O35&" "&P35&" "&Q35&" "&R35&" " -> 3 1.8 0.9 0.9 0.25 0.02 | Z35: 3 | AA35: 1.8 | AB35: 0.9 | AC35: 0.9 | AD35: 0.25 | AE35: 0.02

Sheet C,E,L,M
A1: ='Para. setting'!L1 -> 0 | B1: ='Para. setting'!M1 -> 1 | C1: ='Para. setting'!N1 -> 2 | D1: ='Para. setting'!O1 -> 3 | E1: ='Para. setting'!P1 -> 4 | F1: ='Para. setting'!Q1 -> 5 | G1: Orthogonal Array | N1: run | O1: α | P1: Μ | Q1: ε | R1: Рe | S1: Pm | T1: ρ | V1: ARV | W1: Sum
A2: ='Para. setting'!L2 -> the population size factor | B2: ='Para. setting'!M2 -> 1 | C2: ='Para. setting'!N2 -> 1.5 | D2: ='Para. setting'!O2 -> 2 | E2: ='Para. setting'!P2 -> 2.5 | F2: ='Para. setting'!Q2 -> 3 | G2: 1 | H2: 1 | I2: 1 | J2: 1 | K2: 1 | L2: 1 | N2: 1 | O2: =HLOOKUP(G2,$B$1:$F$7,2) -> 1 | P2: =HLOOKUP(H2,$B$1:$F$7,3) -> 1 | Q2: =HLOOKUP(I2,$B$1:$F$7,4) -> 0.5 | R2: =HLOOKUP(J2,$B$1:$F$7,5) -> 0.7 | S2: =HLOOKUP(K2,$B$1:$F$7,6) -> 0.05 | T2: =HLOOKUP(L2,$B$1:$F$7,7) -> 0.02 | V2: =W2/360 -> 0.0057386711 | W2: =Total!AH4 -> 2.0659216
A3: ='Para. setting'!L3 -> the scale factor | B3: ='Para. setting'!M3 -> 1 | C3: ='Para. setting'!N3 -> 1.2 | D3: ='Para. setting'!O3 -> 1.4 | E3: ='Para. setting'!P3 -> 1.6 | F3: ='Para. setting'!Q3 -> 1.8 | G3: 1 | H3: 2 | I3: 3 | J3: 4 | K3: 5 | L3: 2 | N3: 2 | O3: =HLOOKUP(G3,$B$1:$F$7,2) -> 1 | P3: =HLOOKUP(H3,$B$1:$F$7,3) -> 1.2 | Q3: =HLOOKUP(I3,$B$1:$F$7,4) -> 0.7 | R3: =HLOOKUP(J3,$B$1:$F$7,5) -> 0.85 | S3: =HLOOKUP(K3,$B$1:$F$7,6) -> 0.25 | T3: =HLOOKUP(L3,$B$1:$F$7,7) -> 0.04 | V3: =W3/360 -> 0.0053814556 | W3: =Total!AH5 -> 1.937324
A4: ='Para. setting'!L4 -> the weight factor | B4: ='Para. setting'!M4 -> 0.5 | C4: ='Para. setting'!N4 -> 0.6 | D4: ='Para. setting'!O4 -> 0.7 | E4: ='Para. setting'!P4 -> 0.8 | F4: ='Para. setting'!Q4 -> 0.9 | G4: 1 | H4: 3 | I4: 5 | J4: 2 | K4: 4 | L4: 3 | N4: 3 | O4: =HLOOKUP(G4,$B$1:$F$7,2) -> 1 | P4: =HLOOKUP(H4,$B$1:$F$7,3) -> 1.4 | Q4: =HLOOKUP(I4,$B$1:$F$7,4) -> 0.9 | R4: =HLOOKUP(J4,$B$1:$F$7,5) -> 0.75 | S4: =HLOOKUP(K4,$B$1:$F$7,6) -> 0.2 | T4: =HLOOKUP(L4,$B$1:$F$7,7) -> 0.06 | V4: =W4/360 -> 0.0058915393 | W4: =Total!AH6 -> 2.1209541
A5: ='Para. setting'!L5 -> the biases rate | B5: ='Para. setting'!M5 -> 0.7 | C5: ='Para. setting'!N5 -> 0.75 | D5: ='Para. setting'!O5 -> 0.8 | E5: ='Para. setting'!P5 -> 0.85 | F5: ='Para. setting'!Q5 -> 0.9 | G5: 1 | H5: 4 | I5: 2 | J5: 5 | K5: 3 | L5: 4 | N5: 4 | O5: =HLOOKUP(G5,$B$1:$F$7,2) -> 1 | P5: =HLOOKUP(H5,$B$1:$F$7,3) -> 1.6 | Q5: =HLOOKUP(I5,$B$1:$F$7,4) -> 0.6 | R5: =HLOOKUP(J5,$B$1:$F$7,5) -> 0.9 | S5: =HLOOKUP(K5,$B$1:$F$7,6) -> 0.15 | T5: =HLOOKUP(L5,$B$1:$F$7,7) -> 0.08 | V5: =W5/360 -> 0.0058059876 | W5: =Total!AH7 -> 2.0901555
A6: ='Para. setting'!L6 -> the immigration rate | B6: ='Para. setting'!M6 -> 0.05 | C6: ='Para. setting'!N6 -> 0.1 | D6: ='Para. setting'!O6 -> 0.15 | E6: ='Para. setting'!P6 -> 0.2 | F6: ='Para. setting'!Q6 -> 0.25 | G6: 1 | H6: 5 | I6: 4 | J6: 3 | K6: 2 | L6: 5 | N6: 5 | O6: =HLOOKUP(G6,$B$1:$F$7,2) -> 1 | P6: =HLOOKUP(H6,$B$1:$F$7,3) -> 1.8 | Q6: =HLOOKUP(I6,$B$1:$F$7,4) -> 0.8 | R6: =HLOOKUP(J6,$B$1:$F$7,5) -> 0.8 | S6: =HLOOKUP(K6,$B$1:$F$7,6) -> 0.1 | T6: =HLOOKUP(L6,$B$1:$F$7,7) -> 0.1 | V6: =W6/360 -> 0.00594341 | W6: =Total!AH8 -> 2.1396276
A7: ='Para. setting'!L7 -> the improvement rate | B7: ='Para. setting'!M7 -> 0.02 | C7: ='Para. setting'!N7 -> 0.04 | D7: ='Para. setting'!O7 -> 0.06 | E7: ='Para. setting'!P7 -> 0.08 | F7: ='Para. setting'!Q7 -> 0.1 | G7: 2 | H7: 1 | I7: 5 | J7: 4 | K7: 3 | L7: 5 | N7: 6 | O7: =HLOOKUP(G7,$B$1:$F$7,2) -> 1.5 | P7: =HLOOKUP(H7,$B$1:$F$7,3) -> 1 | Q7: =HLOOKUP(I7,$B$1:$F$7,4) -> 0.9 | R7: =HLOOKUP(J7,$B$1:$F$7,5) -> 0.85 | S7: =HLOOKUP(K7,$B$1:$F$7,6) -> 0.15 | T7: =HLOOKUP(L7,$B$1:$F$7,7) -> 0.1 | V7: =W7/360 -> 0.0051608293 | W7: =Total!AH9 -> 1.8578986
G8: 2 | H8: 2 | I8: 2 | J8: 2 | K8: 2 | L8: 1 | N8: 7 | O8: =HLOOKUP(G8,$B$1:$F$7,2) -> 1.5 | P8: =HLOOKUP(H8,$B$1:$F$7,3) -> 1.2 | Q8: =HLOOKUP(I8,$B$1:$F$7,4) -> 0.6 | R8: =HLOOKUP(J8,$B$1:$F$7,5) -> 0.75 | S8: =HLOOKUP(K8,$B$1:$F$7,6) -> 0.1 | T8: =HLOOKUP(L8,$B$1:$F$7,7) -> 0.02 | V8: =W8/360 -> 0.0047613997 | W8: =Total!AH10 -> 1.7141039
G9: 2 | H9: 3 | I9: 4 | J9: 5 | K9: 1 | L9: 2 | N9: 8 | O9: =HLOOKUP(G9,$B$1:$F$7,2) -> 1.5 | P9: =HLOOKUP(H9,$B$1:$F$7,3) -> 1.4 | Q9: =HLOOKUP(I9,$B$1:$F$7,4) -> 0.8 | R9: =HLOOKUP(J9,$B$1:$F$7,5) -> 0.9 | S9: =HLOOKUP(K9,$B$1:$F$7,6) -> 0.05 | T9: =HLOOKUP(L9,$B$1:$F$7,7) -> 0.04 | V9: =W9/360 -> 0.0053857261 | W9: =Total!AH11 -> 1.9388614
G10: 2 | H10: 4 | I10: 1 | J10: 3 | K10: 5 | L10: 3 | N10: 9 | O10: =HLOOKUP(G10,$B$1:$F$7,2) -> 1.5 | P10: =HLOOKUP(H10,$B$1:$F$7,3) -> 1.6 | Q10: =HLOOKUP(I10,$B$1:$F$7,4) -> 0.5 | R10: =HLOOKUP(J10,$B$1:$F$7,5) -> 0.8 | S10: =HLOOKUP(K10,$B$1:$F$7,6) -> 0.25 | T10: =HLOOKUP(L10,$B$1:$F$7,7) -> 0.06 | V10: =W10/360 -> 0.0054805966 | W10: =Total!AH12 -> 1.9730148
G11: 2 | H11: 5 | I11: 3 | J11: 1 | K11: 4 | L11: 4 | N11: 10 | O11: =HLOOKUP(G11,$B$1:$F$7,2) -> 1.5 | P11: =HLOOKUP(H11,$B$1:$F$7,3) -> 1.8 | Q11: =HLOOKUP(I11,$B$1:$F$7,4) -> 0.7 | R11: =HLOOKUP(J11,$B$1:$F$7,5) -> 0.7 | S11: =HLOOKUP(K11,$B$1:$F$7,6) -> 0.2 | T11: =HLOOKUP(L11,$B$1:$F$7,7) -> 0.08 | V11: =W11/360 -> 0.0052315982 | W11: =Total!AH13 -> 1.8833754
G12: 3 | H12: 1 | I12: 4 | J12: 2 | K12: 5 | L12: 4 | N12: 11 | O12: =HLOOKUP(G12,$B$1:$F$7,2) -> 2 | P12: =HLOOKUP(H12,$B$1:$F$7,3) -> 1 | Q12: =HLOOKUP(I12,$B$1:$F$7,4) -> 0.8 | R12: =HLOOKUP(J12,$B$1:$F$7,5) -> 0.75 | S12: =HLOOKUP(K12,$B$1:$F$7,6) -> 0.25 | T12: =HLOOKUP(L12,$B$1:$F$7,7) -> 0.08 | V12: =W12/360 -> 0.00530933 | W12: =Total!AH14 -> 1.9113588
G13: 3 | H13: 2 | I13: 1 | J13: 5 | K13: 4 | L13: 5 | N13: 12 | O13: =HLOOKUP(G13,$B$1:$F$7,2) -> 2 | P13: =HLOOKUP(H13,$B$1:$F$7,3) -> 1.2 | Q13: =HLOOKUP(I13,$B$1:$F$7,4) -> 0.5 | R13: =HLOOKUP(J13,$B$1:$F$7,5) -> 0.9 | S13: =HLOOKUP(K13,$B$1:$F$7,6) -> 0.2 | T13: =HLOOKUP(L13,$B$1:$F$7,7) -> 0.1 | V13: =W13/360 -> 0.0056132614 | W13: =Total!AH15 -> 2.0207741
G14: 3 | H14: 3 | I14: 3 | J14: 3 | K14: 3 | L14: 1 | N14: 13 | O14: =HLOOKUP(G14,$B$1:$F$7,2) -> 2 | P14: =HLOOKUP(H14,$B$1:$F$7,3) -> 1.4 | Q14: =HLOOKUP(I14,$B$1:$F$7,4) -> 0.7 | R14: =HLOOKUP(J14,$B$1:$F$7,5) -> 0.8 | S14: =HLOOKUP(K14,$B$1:$F$7,6) -> 0.15 | T14: =HLOOKUP(L14,$B$1:$F$7,7) -> 0.02 | V14: =W14/360 -> 0.0051009231 | W14: =Total!AH16 -> 1.8363323
G15: 3 | H15: 4 | I15: 5 | J15: 1 | K15: 2 | L15: 2 | N15: 14 | O15: =HLOOKUP(G15,$B$1:$F$7,2) -> 2 | P15: =HLOOKUP(H15,$B$1:$F$7,3) -> 1.6 | Q15: =HLOOKUP(I15,$B$1:$F$7,4) -> 0.9 | R15: =HLOOKUP(J15,$B$1:$F$7,5) -> 0.7 | S15: =HLOOKUP(K15,$B$1:$F$7,6) -> 0.1 | T15: =HLOOKUP(L15,$B$1:$F$7,7) -> 0.04 | V15: =W15/360 -> 0.0047320735 | W15: =Total!AH17 -> 1.7035465
G16: 3 | H16: 5 | I16: 2 | J16: 4 | K16: 1 | L16: 3 | N16: 15 | O16: =HLOOKUP(G16,$B$1:$F$7,2) -> 2 | P16: =HLOOKUP(H16,$B$1:$F$7,3) -> 1.8 | Q16: =HLOOKUP(I16,$B$1:$F$7,4) -> 0.6 | R16: =HLOOKUP(J16,$B$1:$F$7,5) -> 0.85 | S16: =HLOOKUP(K16,$B$1:$F$7,6) -> 0.05 | T16: =HLOOKUP(L16,$B$1:$F$7,7) -> 0.06 | V16: =W16/360 -> 0.0051971753 | W16: =Total!AH18 -> 1.8709831
G17: 4 | H17: 1 | I17: 3 | J17: 5 | K17: 2 | L17: 3 | N17: 16 | O17: =HLOOKUP(G17,$B$1:$F$7,2) -> 2.5 | P17: =HLOOKUP(H17,$B$1:$F$7,3) -> 1 | Q17: =HLOOKUP(I17,$B$1:$F$7,4) -> 0.7 | R17: =HLOOKUP(J17,$B$1:$F$7,5) -> 0.9 | S17: =HLOOKUP(K17,$B$1:$F$7,6) -> 0.1 | T17: =HLOOKUP(L17,$B$1:$F$7,7) -> 0.06 | V17: =W17/360 -> 0.0048803356 | W17: =Total!AH19 -> 1.7569208
G18: 4 | H18: 2 | I18: 5 | J18: 3 | K18: 1 | L18: 4 | N18: 17 | O18: =HLOOKUP(G18,$B$1:$F$7,2) -> 2.5 | P18: =HLOOKUP(H18,$B$1:$F$7,3) -> 1.2 | Q18: =HLOOKUP(I18,$B$1:$F$7,4) -> 0.9 | R18: =HLOOKUP(J18,$B$1:$F$7,5) -> 0.8 | S18: =HLOOKUP(K18,$B$1:$F$7,6) -> 0.05 | T18: =HLOOKUP(L18,$B$1:$F$7,7) -> 0.08 | V18: =W18/360 -> 0.0046017785 | W18: =Total!AH20 -> 1.6566402
G19: 4 | H19: 3 | I19: 2 | J19: 1 | K19: 5 | L19: 5 | N19: 18 | O19: =HLOOKUP(G19,$B$1:$F$7,2) -> 2.5 | P19: =HLOOKUP(H19,$B$1:$F$7,3) -> 1.4 | Q19: =HLOOKUP(I19,$B$1:$F$7,4) -> 0.6 | R19: =HLOOKUP(J19,$B$1:$F$7,5) -> 0.7 | S19: =HLOOKUP(K19,$B$1:$F$7,6) -> 0.25 | T19: =HLOOKUP(L19,$B$1:$F$7,7) -> 0.1 | V19: =W19/360 -> 0.0061645306 | W19: =Total!AH21 -> 2.219231
... G26: 5 | H26: 5 | I26: 5 | J26: 5 | K26: 5 | L26: 1 | N26: 25 | O26: =HLOOKUP(G26,$B$1:$F$7,2) -> 3 | P26: =HLOOKUP(H26,$B$1:$F$7,3) -> 1.8 | Q26: =HLOOKUP(I26,$B$1:$F$7,4) -> 0.9 | R26: =HLOOKUP(J26,$B$1:$F$7,5) -> 0.9 | S26: =HLOOKUP(K26,$B$1:$F$7,6) -> 0.25 | T26: =HLOOKUP(L26,$B$1:$F$7,7) -> 0.02 | V26: =W26/360 -> 0.0055162062 | W26: =Total!AH28 -> 1.9858342
F27: Level | G27: ε | H27: α | I27: β | J27: Рb | K27: Pm | L27: Pi
F28: 1 | G28: =AVERAGEIF(G2:G26,1,$V$2:$V$26) -> 0.0057522127 | H28: =AVERAGEIF(H2:H26,1,$V$2:$V$26) -> 0.0052227718 | I28: =AVERAGEIF(I2:I26,1,$V$2:$V$26) -> 0.0054819828 | J28: =AVERAGEIF(J2:J26,1,$V$2:$V$26) -> 0.0055351402 | K28: =AVERAGEIF(K2:K26,1,$V$2:$V$26) -> 0.0051249476 | L28: =AVERAGEIF(L2:L26,1,$V$2:$V$26) -> 0.0051945369
F29: 2 | G29: =AVERAGEIF(G2:G26,2,$V$2:$V$26) -> 0.00520403 | H29: =AVERAGEIF(H2:H26,2,$V$2:$V$26) -> 0.0052333446 | I29: =AVERAGEIF(I2:I26,2,$V$2:$V$26) -> 0.0053907572 | J29: =AVERAGEIF(J2:J26,2,$V$2:$V$26) -> 0.0052603526 | K29: =AVERAGEIF(K2:K26,2,$V$2:$V$26) -> 0.0050512993 | L29: =AVERAGEIF(L2:L26,2,$V$2:$V$26) -> 0.005232411
F30: 3 | G30: =AVERAGEIF(G2:G26,3,$V$2:$V$26) -> 0.0051905527 | H30: =AVERAGEIF(H2:H26,3,$V$2:$V$26) -> 0.0054963993 | I30: =AVERAGEIF(I2:I26,3,$V$2:$V$26) -> 0.0050591399 | J30: =AVERAGEIF(J2:J26,3,$V$2:$V$26) -> 0.0052302802 | K30: =AVERAGEIF(K2:K26,3,$V$2:$V$26) -> 0.005502935 | L30: =AVERAGEIF(L2:L26,3,$V$2:$V$26) -> 0.0054516949
F31: 4 | G31: =AVERAGEIF(G2:G26,4,$V$2:$V$26) -> 0.0052280472 | H31: =AVERAGEIF(H2:H26,4,$V$2:$V$26) -> 0.0051151058 | I31: =AVERAGEIF(I2:I26,4,$V$2:$V$26) -> 0.0054605556 | J31: =AVERAGEIF(J2:J26,4,$V$2:$V$26) -> 0.0051068444 | K31: =AVERAGEIF(K2:K26,4,$V$2:$V$26) -> 0.0053233152 | L31: =AVERAGEIF(L2:L26,4,$V$2:$V$26) -> 0.0051775944
F32: 5 | G32: =AVERAGEIF(G2:G26,5,$V$2:$V$26) -> 0.0051980783 | H32: =AVERAGEIF(H2:H26,5,$V$2:$V$26) -> 0.0055052994 | I32: =AVERAGEIF(I2:I26,5,$V$2:$V$26) -> 0.0051804854 | J32: =AVERAGEIF(J2:J26,5,$V$2:$V$26) -> 0.0054403034 | K32: =AVERAGEIF(K2:K26,5,$V$2:$V$26) -> 0.0055704238 | L32: =AVERAGEIF(L2:L26,5,$V$2:$V$26) -> 0.0055166837
G33: =SUM(G28:G32) -> 0.026572921 | H33: =SUM(H28:H32) -> 0.026572921 | I33: =SUM(I28:I32) -> 0.026572921 | J33: =SUM(J28:J32) -> 0.026572921 | K33: =SUM(K28:K32) -> 0.026572921 | L33: =SUM(L28:L32) -> 0.026572921
G34: 2 | H34: 1.6 | I34: 0.7 | J34: 0.85 | K34: 0.1 | L34: 0.08
E36: Range(Delta) | G36: =(MAX(G28:G32)-MIN(G28:G32)) -> 0.00056166003 | H36: =(MAX(H28:H32)-MIN(H28:H32)) -> 0.00039019362 | I36: =(MAX(I28:I32)-MIN(I28:I32)) -> 0.00042284291 | J36: =(MAX(J28:J32)-MIN(J28:J32)) -> 0.00042829578 | K36: =(MAX(K28:K32)-MIN(K28:K32)) -> 0.00051912452 | L36: =(MAX(L28:L32)-MIN(L28:L32)) -> 0.00033908926

Sheet Total
A1: ty | B1: sz | C1: ra | E1: Min | H1: 1 | I1: 2 | J1: 3 | K1: 4 | L1: 5 | M1: 6 | N1: 7 | O1: 8 | P1: 9 | Q1: 10 | R1: 11 | S1: 12 | T1: 13 | U1: 14 | V1: 15 | W1: 16 | X1: 17 | Y1: 18 | Z1: 19 | AA1: 20 | AB1: 21 | AC1: 22 | AD1: 23 | AE1: 24 | AF1: 25 | AH1: C,E,L,M
A2: CyberShake | B2: 30 | C2: 0.4 | E2: =MIN('1:25'!L2:U2) -> 237.17606 | H2: =INDIRECT(COLUMN(A1)&"!AM"&ROW(A1)+1) -> 0 | I2: =INDIRECT(COLUMN(B1)&"!AM"&ROW(B1)+1) -> 0 | J2: =INDIRECT(COLUMN(C1)&"!AM"&ROW(C1)+1) -> 0 | K2: =INDIRECT(COLUMN(D1)&"!AM"&ROW(D1)+1) -> 0 | L2: =INDIRECT(COLUMN(E1)&"!AM"&ROW(E1)+1) -> 0 | M2: =INDIRECT(COLUMN(F1)&"!AM"&ROW(F1)+1) -> 0 | N2: =INDIRECT(COLUMN(G1)&"!AM"&ROW(G1)+1) -> 0 | O2: =INDIRECT(COLUMN(H1)&"!AM"&ROW(H1)+1) -> 0 | ... AF2: =INDIRECT(COLUMN(Y1)&"!AM"&ROW(Y1)+1) -> 0
A3: CyberShake | B3: 30 | C3: 0.7 | E3: =MIN('1:25'!L3:U3) -> 170.35004 | H3: =INDIRECT(COLUMN(A2)&"!AM"&ROW(A2)+1) -> 0 | I3: =INDIRECT(COLUMN(B2)&"!AM"&ROW(B2)+1) -> 0 | J3: =INDIRECT(COLUMN(C2)&"!AM"&ROW(C2)+1) -> 0 | K3: =INDIRECT(COLUMN(D2)&"!AM"&ROW(D2)+1) -> 0 | L3: =INDIRECT(COLUMN(E2)&"!AM"&ROW(E2)+1) -> 0.0012132078 | M3: =INDIRECT(COLUMN(F2)&"!AM"&ROW(F2)+1) -> 0 | N3: =INDIRECT(COLUMN(G2)&"!AM"&ROW(G2)+1) -> 0 | O3: =INDIRECT(COLUMN(H2)&"!AM"&ROW(H2)+1) -> 0.00074364526 | ... AF3: =INDIRECT(COLUMN(Y2)&"!AM"&ROW(Y2)+1) -> 0 | AH3: SUM
A4: CyberShake | B4: 30 | C4: 1 | E4: =MIN('1:25'!L4:U4) -> 156.12667 | H4: =INDIRECT(COLUMN(A3)&"!AM"&ROW(A3)+1) -> 0 | I4: =INDIRECT(COLUMN(B3)&"!AM"&ROW(B3)+1) -> 0 | J4: =INDIRECT(COLUMN(C3)&"!AM"&ROW(C3)+1) -> 0 | K4: =INDIRECT(COLUMN(D3)&"!AM"&ROW(D3)+1) -> 0 | L4: =INDIRECT(COLUMN(E3)&"!AM"&ROW(E3)+1) -> 0 | M4: =INDIRECT(COLUMN(F3)&"!AM"&ROW(F3)+1) -> 0 | N4: =INDIRECT(COLUMN(G3)&"!AM"&ROW(G3)+1) -> 0 | O4: =INDIRECT(COLUMN(H3)&"!AM"&ROW(H3)+1) -> 0 | ... AF4: =INDIRECT(COLUMN(Y3)&"!AM"&ROW(Y3)+1) -> 0 | AH4: 2.0659216
A5: CyberShake | B5: 50 | C5: 0.4 | E5: =MIN('1:25'!L5:U5) -> 491.35005 | H5: =INDIRECT(COLUMN(A4)&"!AM"&ROW(A4)+1) -> 0 | I5: =INDIRECT(COLUMN(B4)&"!AM"&ROW(B4)+1) -> 0 | J5: =INDIRECT(COLUMN(C4)&"!AM"&ROW(C4)+1) -> 0 | K5: =INDIRECT(COLUMN(D4)&"!AM"&ROW(D4)+1) -> 0 | L5: =INDIRECT(COLUMN(E4)&"!AM"&ROW(E4)+1) -> 0 | M5: =INDIRECT(COLUMN(F4)&"!AM"&ROW(F4)+1) -> 0 | N5: =INDIRECT(COLUMN(G4)&"!AM"&ROW(G4)+1) -> 0 | O5: =INDIRECT(COLUMN(H4)&"!AM"&ROW(H4)+1) -> 0 | ... AF5: =INDIRECT(COLUMN(Y4)&"!AM"&ROW(Y4)+1) -> 0 | AH5: 1.937324
A6: CyberShake | B6: 50 | C6: 0.7 | E6: =MIN('1:25'!L6:U6) -> 203.32952 | H6: =INDIRECT(COLUMN(A5)&"!AM"&ROW(A5)+1) -> 0 | I6: =INDIRECT(COLUMN(B5)&"!AM"&ROW(B5)+1) -> 0 | J6: =INDIRECT(COLUMN(C5)&"!AM"&ROW(C5)+1) -> 0 | K6: =INDIRECT(COLUMN(D5)&"!AM"&ROW(D5)+1) -> 0 | L6: =INDIRECT(COLUMN(E5)&"!AM"&ROW(E5)+1) -> 0 | M6: =INDIRECT(COLUMN(F5)&"!AM"&ROW(F5)+1) -> 0 | N6: =INDIRECT(COLUMN(G5)&"!AM"&ROW(G5)+1) -> 0 | O6: =INDIRECT(COLUMN(H5)&"!AM"&ROW(H5)+1) -> 0 | ... AF6: =INDIRECT(COLUMN(Y5)&"!AM"&ROW(Y5)+1) -> 0 | AH6: 2.1209541
A7: CyberShake | B7: 50 | C7: 1 | E7: =MIN('1:25'!L7:U7) -> 179.67333 | H7: =INDIRECT(COLUMN(A6)&"!AM"&ROW(A6)+1) -> 0.10708746 | I7: =INDIRECT(COLUMN(B6)&"!AM"&ROW(B6)+1) -> 0.12086045 | J7: =INDIRECT(COLUMN(C6)&"!AM"&ROW(C6)+1) -> 0.040200068 | K7: =INDIRECT(COLUMN(D6)&"!AM"&ROW(D6)+1) -> 0.11375099 | L7: =INDIRECT(COLUMN(E6)&"!AM"&ROW(E6)+1) -> 0.085579145 | M7: =INDIRECT(COLUMN(F6)&"!AM"&ROW(F6)+1) -> 0.10676938 | N7: =INDIRECT(COLUMN(G6)&"!AM"&ROW(G6)+1) -> 0.066100239 | O7: =INDIRECT(COLUMN(H6)&"!AM"&ROW(H6)+1) -> 0.073563784 | ... AF7: =INDIRECT(COLUMN(Y6)&"!AM"&ROW(Y6)+1) -> 0.09921222 | AH7: 2.0901555
A8: CyberShake | B8: 100 | C8: 0.4 | E8: =MIN('1:25'!L8:U8) -> 282.75521 | H8: =INDIRECT(COLUMN(A7)&"!AM"&ROW(A7)+1) -> 0 | I8: =INDIRECT(COLUMN(B7)&"!AM"&ROW(B7)+1) -> 0 | J8: =INDIRECT(COLUMN(C7)&"!AM"&ROW(C7)+1) -> 0 | K8: =INDIRECT(COLUMN(D7)&"!AM"&ROW(D7)+1) -> 0 | L8: =INDIRECT(COLUMN(E7)&"!AM"&ROW(E7)+1) -> 0 | M8: =INDIRECT(COLUMN(F7)&"!AM"&ROW(F7)+1) -> 0 | N8: =INDIRECT(COLUMN(G7)&"!AM"&ROW(G7)+1) -> 0 | O8: =INDIRECT(COLUMN(H7)&"!AM"&ROW(H7)+1) -> 0 | ... AF8: =INDIRECT(COLUMN(Y7)&"!AM"&ROW(Y7)+1) -> 0 | AH8: 2.1396276
A9: CyberShake | B9: 100 | C9: 0.7 | E9: =MIN('1:25'!L9:U9) -> 255.1888 | H9: =INDIRECT(COLUMN(A8)&"!AM"&ROW(A8)+1) -> 0.097034078 | I9: =INDIRECT(COLUMN(B8)&"!AM"&ROW(B8)+1) -> 0.12396128 | J9: =INDIRECT(COLUMN(C8)&"!AM"&ROW(C8)+1) -> 0.11974276 | K9: =INDIRECT(COLUMN(D8)&"!AM"&ROW(D8)+1) -> 0.12257 | L9: =INDIRECT(COLUMN(E8)&"!AM"&ROW(E8)+1) -> 0.12173536 | M9: =INDIRECT(COLUMN(F8)&"!AM"&ROW(F8)+1) -> 0.098223511 | N9: =INDIRECT(COLUMN(G8)&"!AM"&ROW(G8)+1) -> 0.087124121 | O9: =INDIRECT(COLUMN(H8)&"!AM"&ROW(H8)+1) -> 0.14736959 | ... AF9: =INDIRECT(COLUMN(Y8)&"!AM"&ROW(Y8)+1) -> 0.11094488 | AH9: 1.8578986
A10: CyberShake | B10: 100 | C10: 1 | E10: =MIN('1:25'!L10:U10) -> 238.77667 | H10: =INDIRECT(COLUMN(A9)&"!AM"&ROW(A9)+1) -> 0.027506079 | I10: =INDIRECT(COLUMN(B9)&"!AM"&ROW(B9)+1) -> 0.037710091 | J10: =INDIRECT(COLUMN(C9)&"!AM"&ROW(C9)+1) -> 0.058143913 | K10: =INDIRECT(COLUMN(D9)&"!AM"&ROW(D9)+1) -> 0.053672622 | L10: =INDIRECT(COLUMN(E9)&"!AM"&ROW(E9)+1) -> 0.077586014 | M10: =INDIRECT(COLUMN(F9)&"!AM"&ROW(F9)+1) -> 0.07673815 | N10: =INDIRECT(COLUMN(G9)&"!AM"&ROW(G9)+1) -> 0.036203998 | O10: =INDIRECT(COLUMN(H9)&"!AM"&ROW(H9)+1) -> 0.058589518 | ... AF10: =INDIRECT(COLUMN(Y9)&"!AM"&ROW(Y9)+1) -> 0.045853265 | AH10: 1.7141039
A11: Epigenomics | B11: 24 | C11: 0.4 | E11: =MIN('1:25'!L11:U11) -> 3177.638 | H11: =INDIRECT(COLUMN(A10)&"!AM"&ROW(A10)+1) -> 0 | I11: =INDIRECT(COLUMN(B10)&"!AM"&ROW(B10)+1) -> 0 | J11: =INDIRECT(COLUMN(C10)&"!AM"&ROW(C10)+1) -> 0 | K11: =INDIRECT(COLUMN(D10)&"!AM"&ROW(D10)+1) -> 0 | L11: =INDIRECT(COLUMN(E10)&"!AM"&ROW(E10)+1) -> 0 | M11: =INDIRECT(COLUMN(F10)&"!AM"&ROW(F10)+1) -> 0 | N11: =INDIRECT(COLUMN(G10)&"!AM"&ROW(G10)+1) -> 0 | O11: =INDIRECT(COLUMN(H10)&"!AM"&ROW(H10)+1) -> 0 | ... AF11: =INDIRECT(COLUMN(Y10)&"!AM"&ROW(Y10)+1) -> 0 | AH11: 1.9388614
A12: Epigenomics | B12: 24 | C12: 0.7 | E12: =MIN('1:25'!L12:U12) -> 2321.0359 | H12: =INDIRECT(COLUMN(A11)&"!AM"&ROW(A11)+1) -> 0 | I12: =INDIRECT(COLUMN(B11)&"!AM"&ROW(B11)+1) -> 0 | J12: =INDIRECT(COLUMN(C11)&"!AM"&ROW(C11)+1) -> 0 | K12: =INDIRECT(COLUMN(D11)&"!AM"&ROW(D11)+1) -> 0 | L12: =INDIRECT(COLUMN(E11)&"!AM"&ROW(E11)+1) -> 0 | M12: =INDIRECT(COLUMN(F11)&"!AM"&ROW(F11)+1) -> 0 | N12: =INDIRECT(COLUMN(G11)&"!AM"&ROW(G11)+1) -> 0 | O12: =INDIRECT(COLUMN(H11)&"!AM"&ROW(H11)+1) -> 0 | ... AF12: =INDIRECT(COLUMN(Y11)&"!AM"&ROW(Y11)+1) -> 0 | AH12: 1.9730148
A13: Epigenomics | B13: 24 | C13: 1 | E13: =MIN('1:25'!L13:U13) -> 2320.9075 | H13: =INDIRECT(COLUMN(A12)&"!AM"&ROW(A12)+1) -> 0 | I13: =INDIRECT(COLUMN(B12)&"!AM"&ROW(B12)+1) -> 0 | J13: =INDIRECT(COLUMN(C12)&"!AM"&ROW(C12)+1) -> 0 | K13: =INDIRECT(COLUMN(D12)&"!AM"&ROW(D12)+1) -> 0 | L13: =INDIRECT(COLUMN(E12)&"!AM"&ROW(E12)+1) -> 0 | M13: =INDIRECT(COLUMN(F12)&"!AM"&ROW(F12)+1) -> 0 | N13: =INDIRECT(COLUMN(G12)&"!AM"&ROW(G12)+1) -> 0 | O13: =INDIRECT(COLUMN(H12)&"!AM"&ROW(H12)+1) -> 0 | ... AF13: =INDIRECT(COLUMN(Y12)&"!AM"&ROW(Y12)+1) -> 0 | AH13: 1.8833754
A14: Epigenomics | B14: 47 | C14: 0.4 | E14: =MIN('1:25'!L14:U14) -> 4348.0289 | H14: =INDIRECT(COLUMN(A13)&"!AM"&ROW(A13)+1) -> 0.0019404793 | I14: =INDIRECT(COLUMN(B13)&"!AM"&ROW(B13)+1) -> 0.0025873057 | J14: =INDIRECT(COLUMN(C13)&"!AM"&ROW(C13)+1) -> 0.0025873057 | K14: =INDIRECT(COLUMN(D13)&"!AM"&ROW(D13)+1) -> 0.00064682642 | L14: =INDIRECT(COLUMN(E13)&"!AM"&ROW(E13)+1) -> 0 | M14: =INDIRECT(COLUMN(F13)&"!AM"&ROW(F13)+1) -> 0.00020180868 | N14: =INDIRECT(COLUMN(G13)&"!AM"&ROW(G13)+1) -> 0.0025873057 | O14: =INDIRECT(COLUMN(H13)&"!AM"&ROW(H13)+1) -> 0.0019404793 | ... AF14: =INDIRECT(COLUMN(Y13)&"!AM"&ROW(Y13)+1) -> 0.0032341321 | AH14: 1.9113588
A15: Epigenomics | B15: 47 | C15: 0.7 | E15: =MIN('1:25'!L15:U15) -> 4325.2684 | H15: =INDIRECT(COLUMN(A14)&"!AM"&ROW(A14)+1) -> 0 | I15: =INDIRECT(COLUMN(B14)&"!AM"&ROW(B14)+1) -> 0 | J15: =INDIRECT(COLUMN(C14)&"!AM"&ROW(C14)+1) -> 0 | K15: =INDIRECT(COLUMN(D14)&"!AM"&ROW(D14)+1) -> 0 | L15: =INDIRECT(COLUMN(E14)&"!AM"&ROW(E14)+1) -> 0 | M15: =INDIRECT(COLUMN(F14)&"!AM"&ROW(F14)+1) -> 0 | N15: =INDIRECT(COLUMN(G14)&"!AM"&ROW(G14)+1) -> 0 | O15: =INDIRECT(COLUMN(H14)&"!AM"&ROW(H14)+1) -> 0 | ... AF15: =INDIRECT(COLUMN(Y14)&"!AM"&ROW(Y14)+1) -> 0 | AH15: 2.0207741
... A28: Ligo | B28: 100 | C28: 1 | E28: =MIN('1:25'!L28:U28) -> 1753.1198 | H28: =INDIRECT(COLUMN(A27)&"!AM"&ROW(A27)+1) -> 0.01968477 | I28: =INDIRECT(COLUMN(B27)&"!AM"&ROW(B27)+1) -> 0.027795048 | J28: =INDIRECT(COLUMN(C27)&"!AM"&ROW(C27)+1) -> 0.035024731 | K28: =INDIRECT(COLUMN(D27)&"!AM"&ROW(D27)+1) -> 0.031330386 | L28: =INDIRECT(COLUMN(E27)&"!AM"&ROW(E27)+1) -> 0.025923465 | M28: =INDIRECT(COLUMN(F27)&"!AM"&ROW(F27)+1) -> 0.021700451 | N28: =INDIRECT(COLUMN(G27)&"!AM"&ROW(G27)+1) -> 0.019100885 | O28: =INDIRECT(COLUMN(H27)&"!AM"&ROW(H27)+1) -> 0.025621957 | ... AF28: =INDIRECT(COLUMN(Y27)&"!AM"&ROW(Y27)+1) -> 0.020673966 | AH28: 1.9858342
A29: Montage | B29: 25 | C29: 0.4 | E29: =MIN('1:25'!L29:U29) -> 40.89755 | H29: =INDIRECT(COLUMN(A28)&"!AM"&ROW(A28)+1) -> 0.2175656 | I29: =INDIRECT(COLUMN(B28)&"!AM"&ROW(B28)+1) -> 0.24459656 | J29: =INDIRECT(COLUMN(C28)&"!AM"&ROW(C28)+1) -> 0.2446149 | K29: =INDIRECT(COLUMN(D28)&"!AM"&ROW(D28)+1) -> 0.31926118 | L29: =INDIRECT(COLUMN(E28)&"!AM"&ROW(E28)+1) -> 0.26520855 | M29: =INDIRECT(COLUMN(F28)&"!AM"&ROW(F28)+1) -> 0.19054369 | N29: =INDIRECT(COLUMN(G28)&"!AM"&ROW(G28)+1) -> 0.24754295 | O29: =INDIRECT(COLUMN(H28)&"!AM"&ROW(H28)+1) -> 0.28192887 | ... AF29: =INDIRECT(COLUMN(Y28)&"!AM"&ROW(Y28)+1) -> 0.26520855
A30: Montage | B30: 25 | C30: 0.7 | E30: =MIN('1:25'!L30:U30) -> 28.65436 | H30: =INDIRECT(COLUMN(A29)&"!AM"&ROW(A29)+1) -> 0 | I30: =INDIRECT(COLUMN(B29)&"!AM"&ROW(B29)+1) -> 0.00019682869 | J30: =INDIRECT(COLUMN(C29)&"!AM"&ROW(C29)+1) -> 6.5609562e-05 | K30: =INDIRECT(COLUMN(D29)&"!AM"&ROW(D29)+1) -> 0.0019312942 | L30: =INDIRECT(COLUMN(E29)&"!AM"&ROW(E29)+1) -> 0 | M30: =INDIRECT(COLUMN(F29)&"!AM"&ROW(F29)+1) -> 0.0010968662 | N30: =INDIRECT(COLUMN(G29)&"!AM"&ROW(G29)+1) -> 0 | O30: =INDIRECT(COLUMN(H29)&"!AM"&ROW(H29)+1) -> 0.0013802437 | ... AF30: =INDIRECT(COLUMN(Y29)&"!AM"&ROW(Y29)+1) -> 0
A31: Montage | B31: 25 | C31: 1 | E31: =MIN('1:25'!L31:U31) -> 28.5041 | H31: =INDIRECT(COLUMN(A30)&"!AM"&ROW(A30)+1) -> 0.02459576 | I31: =INDIRECT(COLUMN(B30)&"!AM"&ROW(B30)+1) -> 0.027181002 | J31: =INDIRECT(COLUMN(C30)&"!AM"&ROW(C30)+1) -> 0.023090362 | K31: =INDIRECT(COLUMN(D30)&"!AM"&ROW(D30)+1) -> 0.029609775 | L31: =INDIRECT(COLUMN(E30)&"!AM"&ROW(E30)+1) -> 0.027504815 | M31: =INDIRECT(COLUMN(F30)&"!AM"&ROW(F30)+1) -> 0.027810034 | N31: =INDIRECT(COLUMN(G30)&"!AM"&ROW(G30)+1) -> 0.023306823 | O31: =INDIRECT(COLUMN(H30)&"!AM"&ROW(H30)+1) -> 0.02655197 | ... AF31: =INDIRECT(COLUMN(Y30)&"!AM"&ROW(Y30)+1) -> 0.028389249
A32: Montage | B32: 50 | C32: 0.4 | E32: =MIN('1:25'!L32:U32) -> 56.51134 | H32: =INDIRECT(COLUMN(A31)&"!AM"&ROW(A31)+1) -> 0.41749231 | I32: =INDIRECT(COLUMN(B31)&"!AM"&ROW(B31)+1) -> 0.31903756 | J32: =INDIRECT(COLUMN(C31)&"!AM"&ROW(C31)+1) -> 0.31933325 | K32: =INDIRECT(COLUMN(D31)&"!AM"&ROW(D31)+1) -> 0.47709327 | L32: =INDIRECT(COLUMN(E31)&"!AM"&ROW(E31)+1) -> 0.32154644 | M32: =INDIRECT(COLUMN(F31)&"!AM"&ROW(F31)+1) -> 0.28633209 | N32: =INDIRECT(COLUMN(G31)&"!AM"&ROW(G31)+1) -> 0.21981447 | O32: =INDIRECT(COLUMN(H31)&"!AM"&ROW(H31)+1) -> 0.37664777 | ... AF32: =INDIRECT(COLUMN(Y31)&"!AM"&ROW(Y31)+1) -> 0.50138839
A33: Montage | B33: 50 | C33: 0.7 | E33: =MIN('1:25'!L33:U33) -> 53.11507 | H33: =INDIRECT(COLUMN(A32)&"!AM"&ROW(A32)+1) -> 0.11045867 | I33: =INDIRECT(COLUMN(B32)&"!AM"&ROW(B32)+1) -> 0.07617838 | J33: =INDIRECT(COLUMN(C32)&"!AM"&ROW(C32)+1) -> 0.106155 | K33: =INDIRECT(COLUMN(D32)&"!AM"&ROW(D32)+1) -> 0.10147986 | L33: =INDIRECT(COLUMN(E32)&"!AM"&ROW(E32)+1) -> 0.10306792 | M33: =INDIRECT(COLUMN(F32)&"!AM"&ROW(F32)+1) -> 0.10837772 | N33: =INDIRECT(COLUMN(G32)&"!AM"&ROW(G32)+1) -> 0.080358173 | O33: =INDIRECT(COLUMN(H32)&"!AM"&ROW(H32)+1) -> 0.093152471 | ... AF33: =INDIRECT(COLUMN(Y32)&"!AM"&ROW(Y32)+1) -> 0.065532626
A34: Montage | B34: 50 | C34: 1 | E34: =MIN('1:25'!L34:U34) -> 53.00374 | H34: =INDIRECT(COLUMN(A33)&"!AM"&ROW(A33)+1) -> 0.067591834 | I34: =INDIRECT(COLUMN(B33)&"!AM"&ROW(B33)+1) -> 0.058480024 | J34: =INDIRECT(COLUMN(C33)&"!AM"&ROW(C33)+1) -> 0.058237966 | K34: =INDIRECT(COLUMN(D33)&"!AM"&ROW(D33)+1) -> 0.068570444 | L34: =INDIRECT(COLUMN(E33)&"!AM"&ROW(E33)+1) -> 0.068183868 | M34: =INDIRECT(COLUMN(F33)&"!AM"&ROW(F33)+1) -> 0.059285628 | N34: =INDIRECT(COLUMN(G33)&"!AM"&ROW(G33)+1) -> 0.055110073 | O34: =INDIRECT(COLUMN(H33)&"!AM"&ROW(H33)+1) -> 0.062172028 | ... AF34: =INDIRECT(COLUMN(Y33)&"!AM"&ROW(Y33)+1) -> 0.048336966
A35: Montage | B35: 100 | C35: 0.4 | E35: =MIN('1:25'!L35:U35) -> 147.96312 | H35: =INDIRECT(COLUMN(A34)&"!AM"&ROW(A34)+1) -> 0.017578705 | I35: =INDIRECT(COLUMN(B34)&"!AM"&ROW(B34)+1) -> 0.018229543 | J35: =INDIRECT(COLUMN(C34)&"!AM"&ROW(C34)+1) -> 0.019001019 | K35: =INDIRECT(COLUMN(D34)&"!AM"&ROW(D34)+1) -> 0.02580954 | L35: =INDIRECT(COLUMN(E34)&"!AM"&ROW(E34)+1) -> 0.01337117 | M35: =INDIRECT(COLUMN(F34)&"!AM"&ROW(F34)+1) -> 0.019900026 | N35: =INDIRECT(COLUMN(G34)&"!AM"&ROW(G34)+1) -> 0.016186939 | O35: =INDIRECT(COLUMN(H34)&"!AM"&ROW(H34)+1) -> 0.017213749 | ... AF35: =INDIRECT(COLUMN(Y34)&"!AM"&ROW(Y34)+1) -> 0.016163082
A36: Montage | B36: 100 | C36: 0.7 | E36: =MIN('1:25'!L36:U36) -> 107.28163 | H36: =INDIRECT(COLUMN(A35)&"!AM"&ROW(A35)+1) -> 0.082950268 | I36: =INDIRECT(COLUMN(B35)&"!AM"&ROW(B35)+1) -> 0.089706784 | J36: =INDIRECT(COLUMN(C35)&"!AM"&ROW(C35)+1) -> 0.26664444 | K36: =INDIRECT(COLUMN(D35)&"!AM"&ROW(D35)+1) -> 0.07453867 | L36: =INDIRECT(COLUMN(E35)&"!AM"&ROW(E35)+1) -> 0.27923233 | M36: =INDIRECT(COLUMN(F35)&"!AM"&ROW(F35)+1) -> 0.25458422 | N36: =INDIRECT(COLUMN(G35)&"!AM"&ROW(G35)+1) -> 0.075754815 | O36: =INDIRECT(COLUMN(H35)&"!AM"&ROW(H35)+1) -> 0.080211589 | ... AF36: =INDIRECT(COLUMN(Y35)&"!AM"&ROW(Y35)+1) -> 0.07339318
A37: Montage | B37: 100 | C37: 1 | E37: =MIN('1:25'!L37:U37) -> 103.21266 | H37: =INDIRECT(COLUMN(A36)&"!AM"&ROW(A36)+1) -> 0.073807225 | I37: =INDIRECT(COLUMN(B36)&"!AM"&ROW(B36)+1) -> 0.083166445 | J37: =INDIRECT(COLUMN(C36)&"!AM"&ROW(C36)+1) -> 0.065508824 | K37: =INDIRECT(COLUMN(D36)&"!AM"&ROW(D36)+1) -> 0.071680063 | L37: =INDIRECT(COLUMN(E36)&"!AM"&ROW(E36)+1) -> 0.080712289 | M37: =INDIRECT(COLUMN(F36)&"!AM"&ROW(F36)+1) -> 0.063264817 | N37: =INDIRECT(COLUMN(G36)&"!AM"&ROW(G36)+1) -> 0.066928902 | O37: =INDIRECT(COLUMN(H36)&"!AM"&ROW(H36)+1) -> 0.070601513 | ... AF37: =INDIRECT(COLUMN(Y36)&"!AM"&ROW(Y36)+1) -> 0.058451744
E40: C,E,L,M | G40: SUM | H40: =SUM(H2:H37) -> 2.0659216 | I40: =SUM(I2:I37) -> 1.937324 | J40: =SUM(J2:J37) -> 2.1209541 | K40: =SUM(K2:K37) -> 2.0901555 | L40: =SUM(L2:L37) -> 2.1396276 | M40: =SUM(M2:M37) -> 1.8578986 | N40: =SUM(N2:N37) -> 1.7141039 | O40: =SUM(O2:O37) -> 1.9388614 | ... AF40: =SUM(AF2:AF37) -> 1.9858342

Sheet 1
A1: CyberShake | B1: 30 | C1: 0.4 | D1: 237.17606 | E1: 0.54554 | F1: 70 | H1: ty | I1: sz | J1: ra | L1: 1 | M1: 2 | N1: 3 | O1: 4 | P1: 5 | Q1: 6 | R1: 7 | S1: 8 | T1: 9 | U1: 10 | W1: average | Y1: Min | AM1: sum
A2: CyberShake | B2: 30 | C2: 0.4 | D2: 237.17606 | E2: 0.54548 | F2: 70 | H2: CyberShake | I2: 30 | J2: 0.4 | L2: =INDIRECT("D"&1+(ROW(D1)-1)*10+COLUMN(A1)-1) -> 237.17606 | M2: =INDIRECT("D"&1+(ROW(E1)-1)*10+COLUMN(B1)-1) -> 237.17606 | N2: =INDIRECT("D"&1+(ROW(F1)-1)*10+COLUMN(C1)-1) -> 237.17606 | O2: =INDIRECT("D"&1+(ROW(G1)-1)*10+COLUMN(D1)-1) -> 237.17606 | P2: =INDIRECT("D"&1+(ROW(H1)-1)*10+COLUMN(E1)-1) -> 237.17606 | Q2: =INDIRECT("D"&1+(ROW(I1)-1)*10+COLUMN(F1)-1) -> 237.17606 | R2: =INDIRECT("D"&1+(ROW(J1)-1)*10+COLUMN(G1)-1) -> 237.17606 | S2: =INDIRECT("D"&1+(ROW(K1)-1)*10+COLUMN(H1)-1) -> 237.17606 | ... U2: =INDIRECT("D"&1+(ROW(M1)-1)*10+COLUMN(J1)-1) -> 237.17606 | W2: =AVERAGE(L2:U2) -> 237.17606 | Y2: =Total!E2 -> 237.17606 | AB2: =(L2-$Y2)/$Y2 -> 0 | AC2: =(M2-$Y2)/$Y2 -> 0 | AD2: =(N2-$Y2)/$Y2 -> 0 | AE2: =(O2-$Y2)/$Y2 -> 0 | AF2: =(P2-$Y2)/$Y2 -> 0 | AG2: =(Q2-$Y2)/$Y2 -> 0 | AH2: =(R2-$Y2)/$Y2 -> 0 | AI2: =(S2-$Y2)/$Y2 -> 0 | ... AK2: =(U2-$Y2)/$Y2 -> 0 | AM2: =SUM(AB2:AK2) -> 0
A3: CyberShake | B3: 30 | C3: 0.4 | D3: 237.17606 | E3: 0.55406 | F3: 44 | H3: CyberShake | I3: 30 | J3: 0.7 | L3: =INDIRECT("D"&1+(ROW(D2)-1)*10+COLUMN(A2)-1) -> 170.35004 | M3: =INDIRECT("D"&1+(ROW(E2)-1)*10+COLUMN(B2)-1) -> 170.35004 | N3: =INDIRECT("D"&1+(ROW(F2)-1)*10+COLUMN(C2)-1) -> 170.35004 | O3: =INDIRECT("D"&1+(ROW(G2)-1)*10+COLUMN(D2)-1) -> 170.35004 | P3: =INDIRECT("D"&1+(ROW(H2)-1)*10+COLUMN(E2)-1) -> 170.35004 | Q3: =INDIRECT("D"&1+(ROW(I2)-1)*10+COLUMN(F2)-1) -> 170.35004 | R3: =INDIRECT("D"&1+(ROW(J2)-1)*10+COLUMN(G2)-1) -> 170.35004 | S3: =INDIRECT("D"&1+(ROW(K2)-1)*10+COLUMN(H2)-1) -> 170.35004 | ... U3: =INDIRECT("D"&1+(ROW(M2)-1)*10+COLUMN(J2)-1) -> 170.35004 | W3: =AVERAGE(L3:U3) -> 170.35004 | Y3: =Total!E3 -> 170.35004 | AB3: =(L3-$Y3)/$Y3 -> 0 | AC3: =(M3-$Y3)/$Y3 -> 0 | AD3: =(N3-$Y3)/$Y3 -> 0 | AE3: =(O3-$Y3)/$Y3 -> 0 | AF3: =(P3-$Y3)/$Y3 -> 0 | AG3: =(Q3-$Y3)/$Y3 -> 0 | AH3: =(R3-$Y3)/$Y3 -> 0 | AI3: =(S3-$Y3)/$Y3 -> 0 | ... AK3: =(U3-$Y3)/$Y3 -> 0 | AM3: =SUM(AB3:AK3) -> 0
A4: CyberShake | B4: 30 | C4: 0.4 | D4: 237.17606 | E4: 0.54711 | F4: 59 | H4: CyberShake | I4: 30 | J4: 1 | L4: =INDIRECT("D"&1+(ROW(D3)-1)*10+COLUMN(A3)-1) -> 156.12667 | M4: =INDIRECT("D"&1+(ROW(E3)-1)*10+COLUMN(B3)-1) -> 156.12667 | N4: =INDIRECT("D"&1+(ROW(F3)-1)*10+COLUMN(C3)-1) -> 156.12667 | O4: =INDIRECT("D"&1+(ROW(G3)-1)*10+COLUMN(D3)-1) -> 156.12667 | P4: =INDIRECT("D"&1+(ROW(H3)-1)*10+COLUMN(E3)-1) -> 156.12667 | Q4: =INDIRECT("D"&1+(ROW(I3)-1)*10+COLUMN(F3)-1) -> 156.12667 | R4: =INDIRECT("D"&1+(ROW(J3)-1)*10+COLUMN(G3)-1) -> 156.12667 | S4: =INDIRECT("D"&1+(ROW(K3)-1)*10+COLUMN(H3)-1) -> 156.12667 | ... U4: =INDIRECT("D"&1+(ROW(M3)-1)*10+COLUMN(J3)-1) -> 156.12667 | W4: =AVERAGE(L4:U4) -> 156.12667 | Y4: =Total!E4 -> 156.12667 | AB4: =(L4-$Y4)/$Y4 -> 0 | AC4: =(M4-$Y4)/$Y4 -> 0 | AD4: =(N4-$Y4)/$Y4 -> 0 | AE4: =(O4-$Y4)/$Y4 -> 0 | AF4: =(P4-$Y4)/$Y4 -> 0 | AG4: =(Q4-$Y4)/$Y4 -> 0 | AH4: =(R4-$Y4)/$Y4 -> 0 | AI4: =(S4-$Y4)/$Y4 -> 0 | ... AK4: =(U4-$Y4)/$Y4 -> 0 | AM4: =SUM(AB4:AK4) -> 0
A5: CyberShake | B5: 30 | C5: 0.4 | D5: 237.17606 | E5: 0.56615 | F5: 64 | H5: CyberShake | I5: 50 | J5: 0.4 | L5: =INDIRECT("D"&1+(ROW(D4)-1)*10+COLUMN(A4)-1) -> 491.35005 | M5: =INDIRECT("D"&1+(ROW(E4)-1)*10+COLUMN(B4)-1) -> 491.35005 | N5: =INDIRECT("D"&1+(ROW(F4)-1)*10+COLUMN(C4)-1) -> 491.35005 | O5: =INDIRECT("D"&1+(ROW(G4)-1)*10+COLUMN(D4)-1) -> 491.35005 | P5: =INDIRECT("D"&1+(ROW(H4)-1)*10+COLUMN(E4)-1) -> 491.35005 | Q5: =INDIRECT("D"&1+(ROW(I4)-1)*10+COLUMN(F4)-1) -> 491.35005 | R5: =INDIRECT("D"&1+(ROW(J4)-1)*10+COLUMN(G4)-1) -> 491.35005 | S5: =INDIRECT("D"&1+(ROW(K4)-1)*10+COLUMN(H4)-1) -> 491.35005 | ... U5: =INDIRECT("D"&1+(ROW(M4)-1)*10+COLUMN(J4)-1) -> 491.35005 | W5: =AVERAGE(L5:U5) -> 491.35005 | Y5: =Total!E5 -> 491.35005 | AB5: =(L5-$Y5)/$Y5 -> 0 | AC5: =(M5-$Y5)/$Y5 -> 0 | AD5: =(N5-$Y5)/$Y5 -> 0 | AE5: =(O5-$Y5)/$Y5 -> 0 | AF5: =(P5-$Y5)/$Y5 -> 0 | AG5: =(Q5-$Y5)/$Y5 -> 0 | AH5: =(R5-$Y5)/$Y5 -> 0 | AI5: =(S5-$Y5)/$Y5 -> 0 | ... AK5: =(U5-$Y5)/$Y5 -> 0 | AM5: =SUM(AB5:AK5) -> 0
A6: CyberShake | B6: 30 | C6: 0.4 | D6: 237.17606 | E6: 0.54638 | F6: 66 | H6: CyberShake | I6: 50 | J6: 0.7 | L6: =INDIRECT("D"&1+(ROW(D5)-1)*10+COLUMN(A5)-1) -> 203.32952 | M6: =INDIRECT("D"&1+(ROW(E5)-1)*10+COLUMN(B5)-1) -> 203.32952 | N6: =INDIRECT("D"&1+(ROW(F5)-1)*10+COLUMN(C5)-1) -> 203.32952 | O6: =INDIRECT("D"&1+(ROW(G5)-1)*10+COLUMN(D5)-1) -> 203.32952 | P6: =INDIRECT("D"&1+(ROW(H5)-1)*10+COLUMN(E5)-1) -> 203.32952 | Q6: =INDIRECT("D"&1+(ROW(I5)-1)*10+COLUMN(F5)-1) -> 203.32952 | R6: =INDIRECT("D"&1+(ROW(J5)-1)*10+COLUMN(G5)-1) -> 203.32952 | S6: =INDIRECT("D"&1+(ROW(K5)-1)*10+COLUMN(H5)-1) -> 203.32952 | ... U6: =INDIRECT("D"&1+(ROW(M5)-1)*10+COLUMN(J5)-1) -> 203.32952 | W6: =AVERAGE(L6:U6) -> 203.32952 | Y6: =Total!E6 -> 203.32952 | AB6: =(L6-$Y6)/$Y6 -> 0 | AC6: =(M6-$Y6)/$Y6 -> 0 | AD6: =(N6-$Y6)/$Y6 -> 0 | AE6: =(O6-$Y6)/$Y6 -> 0 | AF6: =(P6-$Y6)/$Y6 -> 0 | AG6: =(Q6-$Y6)/$Y6 -> 0 | AH6: =(R6-$Y6)/$Y6 -> 0 | AI6: =(S6-$Y6)/$Y6 -> 0 | ... AK6: =(U6-$Y6)/$Y6 -> 0 | AM6: =SUM(AB6:AK6) -> 0
A7: CyberShake | B7: 30 | C7: 0.4 | D7: 237.17606 | E7: 0.54833 | F7: 74 | H7: CyberShake | I7: 50 | J7: 1 | L7: =INDIRECT("D"&1+(ROW(D6)-1)*10+COLUMN(A6)-1) -> 182.50635 | M7: =INDIRECT("D"&1+(ROW(E6)-1)*10+COLUMN(B6)-1) -> 179.94333 | N7: =INDIRECT("D"&1+(ROW(F6)-1)*10+COLUMN(C6)-1) -> 181.82816 | O7: =INDIRECT("D"&1+(ROW(G6)-1)*10+COLUMN(D6)-1) -> 179.67333 | P7: =INDIRECT("D"&1+(ROW(H6)-1)*10+COLUMN(E6)-1) -> 182.34583 | Q7: =INDIRECT("D"&1+(ROW(I6)-1)*10+COLUMN(F6)-1) -> 183.85667 | R7: =INDIRECT("D"&1+(ROW(J6)-1)*10+COLUMN(G6)-1) -> 182.37333 | S7: =INDIRECT("D"&1+(ROW(K6)-1)*10+COLUMN(H6)-1) -> 180.33333 | ... U7: =INDIRECT("D"&1+(ROW(M6)-1)*10+COLUMN(J6)-1) -> 182.34583 | W7: =AVERAGE(L7:U7) -> 181.59741 | Y7: =Total!E7 -> 179.67333 | AB7: =(L7-$Y7)/$Y7 -> 0.015767616 | AC7: =(M7-$Y7)/$Y7 -> 0.0015027272 | AD7: =(N7-$Y7)/$Y7 -> 0.011993043 | AE7: =(O7-$Y7)/$Y7 -> 0 | AF7: =(P7-$Y7)/$Y7 -> 0.014874216 | AG7: =(Q7-$Y7)/$Y7 -> 0.023283033 | AH7: =(R7-$Y7)/$Y7 -> 0.015027272 | AI7: =(S7-$Y7)/$Y7 -> 0.0036733332 | ... AK7: =(U7-$Y7)/$Y7 -> 0.014874216 | AM7: =SUM(AB7:AK7) -> 0.10708746
A8: CyberShake | B8: 30 | C8: 0.4 | D8: 237.17606 | E8: 0.54539 | F8: 71 | H8: CyberShake | I8: 100 | J8: 0.4 | L8: =INDIRECT("D"&1+(ROW(D7)-1)*10+COLUMN(A7)-1) -> 282.75521 | M8: =INDIRECT("D"&1+(ROW(E7)-1)*10+COLUMN(B7)-1) -> 282.75521 | N8: =INDIRECT("D"&1+(ROW(F7)-1)*10+COLUMN(C7)-1) -> 282.75521 | O8: =INDIRECT("D"&1+(ROW(G7)-1)*10+COLUMN(D7)-1) -> 282.75521 | P8: =INDIRECT("D"&1+(ROW(H7)-1)*10+COLUMN(E7)-1) -> 282.75521 | Q8: =INDIRECT("D"&1+(ROW(I7)-1)*10+COLUMN(F7)-1) -> 282.75521 | R8: =INDIRECT("D"&1+(ROW(J7)-1)*10+COLUMN(G7)-1) -> 282.75521 | S8: =INDIRECT("D"&1+(ROW(K7)-1)*10+COLUMN(H7)-1) -> 282.75521 | ... U8: =INDIRECT("D"&1+(ROW(M7)-1)*10+COLUMN(J7)-1) -> 282.75521 | W8: =AVERAGE(L8:U8) -> 282.75521 | Y8: =Total!E8 -> 282.75521 | AB8: =(L8-$Y8)/$Y8 -> 0 | AC8: =(M8-$Y8)/$Y8 -> 0 | AD8: =(N8-$Y8)/$Y8 -> 0 | AE8: =(O8-$Y8)/$Y8 -> 0 | AF8: =(P8-$Y8)/$Y8 -> 0 | AG8: =(Q8-$Y8)/$Y8 -> 0 | AH8: =(R8-$Y8)/$Y8 -> 0 | AI8: =(S8-$Y8)/$Y8 -> 0 | ... AK8: =(U8-$Y8)/$Y8 -> 0 | AM8: =SUM(AB8:AK8) -> 0
A9: CyberShake | B9: 30 | C9: 0.4 | D9: 237.17606 | E9: 0.54691 | F9: 74 | H9: CyberShake | I9: 100 | J9: 0.7 | L9: =INDIRECT("D"&1+(ROW(D8)-1)*10+COLUMN(A8)-1) -> 258.40852 | M9: =INDIRECT("D"&1+(ROW(E8)-1)*10+COLUMN(B8)-1) -> 255.89185 | N9: =INDIRECT("D"&1+(ROW(F8)-1)*10+COLUMN(C8)-1) -> 258.20185 | O9: =INDIRECT("D"&1+(ROW(G8)-1)*10+COLUMN(D8)-1) -> 256.27307 | P9: =INDIRECT("D"&1+(ROW(H8)-1)*10+COLUMN(E8)-1) -> 256.57809 | Q9: =INDIRECT("D"&1+(ROW(I8)-1)*10+COLUMN(F8)-1) -> 259.85129 | R9: =INDIRECT("D"&1+(ROW(J8)-1)*10+COLUMN(G8)-1) -> 259.37536 | S9: =INDIRECT("D"&1+(ROW(K8)-1)*10+COLUMN(H8)-1) -> 259.16523 | ... U9: =INDIRECT("D"&1+(ROW(M8)-1)*10+COLUMN(J8)-1) -> 256.158 | W9: =AVERAGE(L9:U9) -> 257.665 | Y9: =Total!E9 -> 255.1888 | AB9: =(L9-$Y9)/$Y9 -> 0.012617011 | AC9: =(M9-$Y9)/$Y9 -> 0.002755019 | AD9: =(N9-$Y9)/$Y9 -> 0.01180714 | AE9: =(O9-$Y9)/$Y9 -> 0.0042488934 | AF9: =(P9-$Y9)/$Y9 -> 0.0054441653 | AG9: =(Q9-$Y9)/$Y9 -> 0.018270747 | AH9: =(R9-$Y9)/$Y9 -> 0.016405736 | AI9: =(S9-$Y9)/$Y9 -> 0.015582306 | ... AK9: =(U9-$Y9)/$Y9 -> 0.0037979723 | AM9: =SUM(AB9:AK9) -> 0.097034078
A10: CyberShake | B10: 30 | C10: 0.4 | D10: 237.17606 | E10: 0.54532 | F10: 65 | H10: CyberShake | I10: 100 | J10: 1 | L10: =INDIRECT("D"&1+(ROW(D9)-1)*10+COLUMN(A9)-1) -> 239.30293 | M10: =INDIRECT("D"&1+(ROW(E9)-1)*10+COLUMN(B9)-1) -> 240.48 | N10: =INDIRECT("D"&1+(ROW(F9)-1)*10+COLUMN(C9)-1) -> 239.2439 | O10: =INDIRECT("D"&1+(ROW(G9)-1)*10+COLUMN(D9)-1) -> 239.24667 | P10: =INDIRECT("D"&1+(ROW(H9)-1)*10+COLUMN(E9)-1) -> 239.41561 | Q10: =INDIRECT("D"&1+(ROW(I9)-1)*10+COLUMN(F9)-1) -> 239.39667 | R10: =INDIRECT("D"&1+(ROW(J9)-1)*10+COLUMN(G9)-1) -> 239.11873 | S10: =INDIRECT("D"&1+(ROW(K9)-1)*10+COLUMN(H9)-1) -> 239.33 | ... U10: =INDIRECT("D"&1+(ROW(M9)-1)*10+COLUMN(J9)-1) -> 239.25 | W10: =AVERAGE(L10:U10) -> 239.43345 | Y10: =Total!E10 -> 238.77667 | AB10: =(L10-$Y10)/$Y10 -> 0.0022039842 | AC10: =(M10-$Y10)/$Y10 -> 0.0071335696 | AD10: =(N10-$Y10)/$Y10 -> 0.0019567657 | AE10: =(O10-$Y10)/$Y10 -> 0.0019683665 | AF10: =(P10-$Y10)/$Y10 -> 0.0026758896 | AG10: =(Q10-$Y10)/$Y10 -> 0.0025965686 | AH10: =(R10-$Y10)/$Y10 -> 0.001432552 | AI10: =(S10-$Y10)/$Y10 -> 0.0023173537 | ... AK10: =(U10-$Y10)/$Y10 -> 0.0019823126 | AM10: =SUM(AB10:AK10) -> 0.027506079
A11: CyberShake | B11: 30 | C11: 0.7 | D11: 170.35004 | E11: 1.44415 | F11: 199 | H11: Epigenomics | I11: 24 | J11: 0.4 | L11: =INDIRECT("D"&1+(ROW(D10)-1)*10+COLUMN(A10)-1) -> 3177.638 | M11: =INDIRECT("D"&1+(ROW(E10)-1)*10+COLUMN(B10)-1) -> 3177.638 | N11: =INDIRECT("D"&1+(ROW(F10)-1)*10+COLUMN(C10)-1) -> 3177.638 | O11: =INDIRECT("D"&1+(ROW(G10)-1)*10+COLUMN(D10)-1) -> 3177.638 | P11: =INDIRECT("D"&1+(ROW(H10)-1)*10+COLUMN(E10)-1) -> 3177.638 | Q11: =INDIRECT("D"&1+(ROW(I10)-1)*10+COLUMN(F10)-1) -> 3177.638 | R11: =INDIRECT("D"&1+(ROW(J10)-1)*10+COLUMN(G10)-1) -> 3177.638 | S11: =INDIRECT("D"&1+(ROW(K10)-1)*10+COLUMN(H10)-1) -> 3177.638 | ... U11: =INDIRECT("D"&1+(ROW(M10)-1)*10+COLUMN(J10)-1) -> 3177.638 | W11: =AVERAGE(L11:U11) -> 3177.638 | Y11: =Total!E11 -> 3177.638 | AB11: =(L11-$Y11)/$Y11 -> 0 | AC11: =(M11-$Y11)/$Y11 -> 0 | AD11: =(N11-$Y11)/$Y11 -> 0 | AE11: =(O11-$Y11)/$Y11 -> 0 | AF11: =(P11-$Y11)/$Y11 -> 0 | AG11: =(Q11-$Y11)/$Y11 -> 0 | AH11: =(R11-$Y11)/$Y11 -> 0 | AI11: =(S11-$Y11)/$Y11 -> 0 | ... AK11: =(U11-$Y11)/$Y11 -> 0 | AM11: =SUM(AB11:AK11) -> 0
A12: CyberShake | B12: 30 | C12: 0.7 | D12: 170.35004 | E12: 1.42232 | F12: 192 | H12: Epigenomics | I12: 24 | J12: 0.7 | L12: =INDIRECT("D"&1+(ROW(D11)-1)*10+COLUMN(A11)-1) -> 2321.0359 | M12: =INDIRECT("D"&1+(ROW(E11)-1)*10+COLUMN(B11)-1) -> 2321.0359 | N12: =INDIRECT("D"&1+(ROW(F11)-1)*10+COLUMN(C11)-1) -> 2321.0359 | O12: =INDIRECT("D"&1+(ROW(G11)-1)*10+COLUMN(D11)-1) -> 2321.0359 | P12: =INDIRECT("D"&1+(ROW(H11)-1)*10+COLUMN(E11)-1) -> 2321.0359 | Q12: =INDIRECT("D"&1+(ROW(I11)-1)*10+COLUMN(F11)-1) -> 2321.0359 | R12: =INDIRECT("D"&1+(ROW(J11)-1)*10+COLUMN(G11)-1) -> 2321.0359 | S12: =INDIRECT("D"&1+(ROW(K11)-1)*10+COLUMN(H11)-1) -> 2321.0359 | ... U12: =INDIRECT("D"&1+(ROW(M11)-1)*10+COLUMN(J11)-1) -> 2321.0359 | W12: =AVERAGE(L12:U12) -> 2321.0359 | Y12: =Total!E12 -> 2321.0359 | AB12: =(L12-$Y12)/$Y12 -> 0 | AC12: =(M12-$Y12)/$Y12 -> 0 | AD12: =(N12-$Y12)/$Y12 -> 0 | AE12: =(O12-$Y12)/$Y12 -> 0 | AF12: =(P12-$Y12)/$Y12 -> 0 | AG12: =(Q12-$Y12)/$Y12 -> 0 | AH12: =(R12-$Y12)/$Y12 -> 0 | AI12: =(S12-$Y12)/$Y12 -> 0 | ... AK12: =(U12-$Y12)/$Y12 -> 0 | AM12: =SUM(AB12:AK12) -> 0
A13: CyberShake | B13: 30 | C13: 0.7 | D13: 170.35004 | E13: 1.42526 | F13: 214 | H13: Epigenomics | I13: 24 | J13: 1 | L13: =INDIRECT("D"&1+(ROW(D12)-1)*10+COLUMN(A12)-1) -> 2320.9075 | M13: =INDIRECT("D"&1+(ROW(E12)-1)*10+COLUMN(B12)-1) -> 2320.9075 | N13: =INDIRECT("D"&1+(ROW(F12)-1)*10+COLUMN(C12)-1) -> 2320.9075 | O13: =INDIRECT("D"&1+(ROW(G12)-1)*10+COLUMN(D12)-1) -> 2320.9075 | P13: =INDIRECT("D"&1+(ROW(H12)-1)*10+COLUMN(E12)-1) -> 2320.9075 | Q13: =INDIRECT("D"&1+(ROW(I12)-1)*10+COLUMN(F12)-1) -> 2320.9075 | R13: =INDIRECT("D"&1+(ROW(J12)-1)*10+COLUMN(G12)-1) -> 2320.9075 | S13: =INDIRECT("D"&1+(ROW(K12)-1)*10+COLUMN(H12)-1) -> 2320.9075 | ... U13: =INDIRECT("D"&1+(ROW(M12)-1)*10+COLUMN(J12)-1) -> 2320.9075 | W13: =AVERAGE(L13:U13) -> 2320.9075 | Y13: =Total!E13 -> 2320.9075 | AB13: =(L13-$Y13)/$Y13 -> 0 | AC13: =(M13-$Y13)/$Y13 -> 0 | AD13: =(N13-$Y13)/$Y13 -> 0 | AE13: =(O13-$Y13)/$Y13 -> 0 | AF13: =(P13-$Y13)/$Y13 -> 0 | AG13: =(Q13-$Y13)/$Y13 -> 0 | AH13: =(R13-$Y13)/$Y13 -> 0 | AI13: =(S13-$Y13)/$Y13 -> 0 | ... AK13: =(U13-$Y13)/$Y13 -> 0 | AM13: =SUM(AB13:AK13) -> 0
... A37: CyberShake | B37: 50 | C37: 0.4 | D37: 491.35005 | E37: 1.20192 | F37: 87 | H37: Montage | I37: 100 | J37: 1 | L37: =INDIRECT("D"&1+(ROW(D36)-1)*10+COLUMN(A36)-1) -> 103.93525 | M37: =INDIRECT("D"&1+(ROW(E36)-1)*10+COLUMN(B36)-1) -> 103.93919 | N37: =INDIRECT("D"&1+(ROW(F36)-1)*10+COLUMN(C36)-1) -> 104.01663 | O37: =INDIRECT("D"&1+(ROW(G36)-1)*10+COLUMN(D36)-1) -> 103.95919 | P37: =INDIRECT("D"&1+(ROW(H36)-1)*10+COLUMN(E36)-1) -> 103.89007 | Q37: =INDIRECT("D"&1+(ROW(I36)-1)*10+COLUMN(F36)-1) -> 103.87174 | R37: =INDIRECT("D"&1+(ROW(J36)-1)*10+COLUMN(G36)-1) -> 104.0358 | S37: =INDIRECT("D"&1+(ROW(K36)-1)*10+COLUMN(H36)-1) -> 104.04496 | ... U37: =INDIRECT("D"&1+(ROW(M36)-1)*10+COLUMN(J36)-1) -> 103.96414 | W37: =AVERAGE(L37:U37) -> 103.97444 | Y37: =Total!E37 -> 103.21266 | AB37: =(L37-$Y37)/$Y37 -> 0.0070009822 | AC37: =(M37-$Y37)/$Y37 -> 0.0070391559 | AD37: =(N37-$Y37)/$Y37 -> 0.0077894514 | AE37: =(O37-$Y37)/$Y37 -> 0.0072329305 | AF37: =(P37-$Y37)/$Y37 -> 0.0065632452 | AG37: =(Q37-$Y37)/$Y37 -> 0.0063856508 | AH37: =(R37-$Y37)/$Y37 -> 0.0079751844 | AI37: =(S37-$Y37)/$Y37 -> 0.0080639332 | ... AK37: =(U37-$Y37)/$Y37 -> 0.0072808898 | AM37: =SUM(AB37:AK37) -> 0.073807225
A38: CyberShake | B38: 50 | C38: 0.4 | D38: 491.35005 | E38: 1.20664 | F38: 86 | H38: Sipht | I38: 29 | J38: 0.4 | L38: =INDIRECT("D"&1+(ROW(D37)-1)*10+COLUMN(A37)-1) -> 1796.8312 | M38: =INDIRECT("D"&1+(ROW(E37)-1)*10+COLUMN(B37)-1) -> 1796.8312 | N38: =INDIRECT("D"&1+(ROW(F37)-1)*10+COLUMN(C37)-1) -> 1796.8312 | O38: =INDIRECT("D"&1+(ROW(G37)-1)*10+COLUMN(D37)-1) -> 1796.8312 | P38: =INDIRECT("D"&1+(ROW(H37)-1)*10+COLUMN(E37)-1) -> 1796.8312 | Q38: =INDIRECT("D"&1+(ROW(I37)-1)*10+COLUMN(F37)-1) -> 1796.8312 | R38: =INDIRECT("D"&1+(ROW(J37)-1)*10+COLUMN(G37)-1) -> 1796.8312 | S38: =INDIRECT("D"&1+(ROW(K37)-1)*10+COLUMN(H37)-1) -> 1796.8312 | ... U38: =INDIRECT("D"&1+(ROW(M37)-1)*10+COLUMN(J37)-1) -> 1796.8312 | W38: =AVERAGE(L38:U38) -> 1796.8312 | Y38: =Total!#REF! -> #REF! | AB38: =(L38-$Y38)/$Y38 -> #REF! | AC38: =(M38-$Y38)/$Y38 -> #REF! | AD38: =(N38-$Y38)/$Y38 -> #REF! | AE38: =(O38-$Y38)/$Y38 -> #REF! | AF38: =(P38-$Y38)/$Y38 -> #REF! | AG38: =(Q38-$Y38)/$Y38 -> #REF! | AH38: =(R38-$Y38)/$Y38 -> #REF! | AI38: =(S38-$Y38)/$Y38 -> #REF! | ... AK38: =(U38-$Y38)/$Y38 -> #REF! | AM38: =SUM(AB38:AK38) -> #REF!
A39: CyberShake | B39: 50 | C39: 0.4 | D39: 491.35005 | E39: 1.20209 | F39: 89 | H39: Sipht | I39: 29 | J39: 0.7 | L39: =INDIRECT("D"&1+(ROW(D38)-1)*10+COLUMN(A38)-1) -> 1469.6411 | M39: =INDIRECT("D"&1+(ROW(E38)-1)*10+COLUMN(B38)-1) -> 1469.6411 | N39: =INDIRECT("D"&1+(ROW(F38)-1)*10+COLUMN(C38)-1) -> 1469.6411 | O39: =INDIRECT("D"&1+(ROW(G38)-1)*10+COLUMN(D38)-1) -> 1469.6411 | P39: =INDIRECT("D"&1+(ROW(H38)-1)*10+COLUMN(E38)-1) -> 1469.6411 | Q39: =INDIRECT("D"&1+(ROW(I38)-1)*10+COLUMN(F38)-1) -> 1469.6411 | R39: =INDIRECT("D"&1+(ROW(J38)-1)*10+COLUMN(G38)-1) -> 1469.6411 | S39: =INDIRECT("D"&1+(ROW(K38)-1)*10+COLUMN(H38)-1) -> 1469.6411 | ... U39: =INDIRECT("D"&1+(ROW(M38)-1)*10+COLUMN(J38)-1) -> 1469.6411 | W39: =AVERAGE(L39:U39) -> 1469.6411 | Y39: =Total!#REF! -> #REF! | AB39: =(L39-$Y39)/$Y39 -> #REF! | AC39: =(M39-$Y39)/$Y39 -> #REF! | AD39: =(N39-$Y39)/$Y39 -> #REF! | AE39: =(O39-$Y39)/$Y39 -> #REF! | AF39: =(P39-$Y39)/$Y39 -> #REF! | AG39: =(Q39-$Y39)/$Y39 -> #REF! | AH39: =(R39-$Y39)/$Y39 -> #REF! | AI39: =(S39-$Y39)/$Y39 -> #REF! | ... AK39: =(U39-$Y39)/$Y39 -> #REF! | AM39: =SUM(AB39:AK39) -> #REF!
A40: CyberShake | B40: 50 | C40: 0.4 | D40: 491.35005 | E40: 1.20555 | F40: 90 | H40: Sipht | I40: 29 | J40: 1 | L40: =INDIRECT("D"&1+(ROW(D39)-1)*10+COLUMN(A39)-1) -> 1469.6411 | M40: =INDIRECT("D"&1+(ROW(E39)-1)*10+COLUMN(B39)-1) -> 1469.6411 | N40: =INDIRECT("D"&1+(ROW(F39)-1)*10+COLUMN(C39)-1) -> 1469.6411 | O40: =INDIRECT("D"&1+(ROW(G39)-1)*10+COLUMN(D39)-1) -> 1469.6411 | P40: =INDIRECT("D"&1+(ROW(H39)-1)*10+COLUMN(E39)-1) -> 1469.6411 | Q40: =INDIRECT("D"&1+(ROW(I39)-1)*10+COLUMN(F39)-1) -> 1469.6411 | R40: =INDIRECT("D"&1+(ROW(J39)-1)*10+COLUMN(G39)-1) -> 1469.6411 | S40: =INDIRECT("D"&1+(ROW(K39)-1)*10+COLUMN(H39)-1) -> 1469.6411 | ... U40: =INDIRECT("D"&1+(ROW(M39)-1)*10+COLUMN(J39)-1) -> 1469.6411 | W40: =AVERAGE(L40:U40) -> 1469.6411 | Y40: =Total!#REF! -> #REF! | AB40: =(L40-$Y40)/$Y40 -> #REF! | AC40: =(M40-$Y40)/$Y40 -> #REF! | AD40: =(N40-$Y40)/$Y40 -> #REF! | AE40: =(O40-$Y40)/$Y40 -> #REF! | AF40: =(P40-$Y40)/$Y40 -> #REF! | AG40: =(Q40-$Y40)/$Y40 -> #REF! | AH40: =(R40-$Y40)/$Y40 -> #REF! | AI40: =(S40-$Y40)/$Y40 -> #REF! | ... AK40: =(U40-$Y40)/$Y40 -> #REF! | AM40: =SUM(AB40:AK40) -> #REF!
A41: CyberShake | B41: 50 | C41: 0.7 | D41: 203.32952 | E41: 2.89028 | F41: 223 | H41: Sipht | I41: 58 | J41: 0.4 | L41: =INDIRECT("D"&1+(ROW(D40)-1)*10+COLUMN(A40)-1) -> 3085.9724 | M41: =INDIRECT("D"&1+(ROW(E40)-1)*10+COLUMN(B40)-1) -> 3085.9724 | N41: =INDIRECT("D"&1+(ROW(F40)-1)*10+COLUMN(C40)-1) -> 3085.9724 | O41: =INDIRECT("D"&1+(ROW(G40)-1)*10+COLUMN(D40)-1) -> 3085.9724 | P41: =INDIRECT("D"&1+(ROW(H40)-1)*10+COLUMN(E40)-1) -> 3085.9724 | Q41: =INDIRECT("D"&1+(ROW(I40)-1)*10+COLUMN(F40)-1) -> 3085.9724 | R41: =INDIRECT("D"&1+(ROW(J40)-1)*10+COLUMN(G40)-1) -> 3085.9724 | S41: =INDIRECT("D"&1+(ROW(K40)-1)*10+COLUMN(H40)-1) -> 3085.9724 | ... U41: =INDIRECT("D"&1+(ROW(M40)-1)*10+COLUMN(J40)-1) -> 3085.9724 | W41: =AVERAGE(L41:U41) -> 3085.9724 | Y41: =Total!#REF! -> #REF! | AB41: =(L41-$Y41)/$Y41 -> #REF! | AC41: =(M41-$Y41)/$Y41 -> #REF! | AD41: =(N41-$Y41)/$Y41 -> #REF! | AE41: =(O41-$Y41)/$Y41 -> #REF! | AF41: =(P41-$Y41)/$Y41 -> #REF! | AG41: =(Q41-$Y41)/$Y41 -> #REF! | AH41: =(R41-$Y41)/$Y41 -> #REF! | AI41: =(S41-$Y41)/$Y41 -> #REF! | ... AK41: =(U41-$Y41)/$Y41 -> #REF! | AM41: =SUM(AB41:AK41) -> #REF!
A42: CyberShake | B42: 50 | C42: 0.7 | D42: 203.32952 | E42: 2.88939 | F42: 236 | H42: Sipht | I42: 58 | J42: 0.7 | L42: =INDIRECT("D"&1+(ROW(D41)-1)*10+COLUMN(A41)-1) -> 1547.1361 | M42: =INDIRECT("D"&1+(ROW(E41)-1)*10+COLUMN(B41)-1) -> 1547.1361 | N42: =INDIRECT("D"&1+(ROW(F41)-1)*10+COLUMN(C41)-1) -> 1547.1361 | O42: =INDIRECT("D"&1+(ROW(G41)-1)*10+COLUMN(D41)-1) -> 1547.1361 | P42: =INDIRECT("D"&1+(ROW(H41)-1)*10+COLUMN(E41)-1) -> 1547.1361 | Q42: =INDIRECT("D"&1+(ROW(I41)-1)*10+COLUMN(F41)-1) -> 1547.1361 | R42: =INDIRECT("D"&1+(ROW(J41)-1)*10+COLUMN(G41)-1) -> 1547.1361 | S42: =INDIRECT("D"&1+(ROW(K41)-1)*10+COLUMN(H41)-1) -> 1547.1361 | ... U42: =INDIRECT("D"&1+(ROW(M41)-1)*10+COLUMN(J41)-1) -> 1547.1361 | W42: =AVERAGE(L42:U42) -> 1547.1361 | Y42: =Total!#REF! -> #REF! | AB42: =(L42-$Y42)/$Y42 -> #REF! | AC42: =(M42-$Y42)/$Y42 -> #REF! | AD42: =(N42-$Y42)/$Y42 -> #REF! | AE42: =(O42-$Y42)/$Y42 -> #REF! | AF42: =(P42-$Y42)/$Y42 -> #REF! | AG42: =(Q42-$Y42)/$Y42 -> #REF! | AH42: =(R42-$Y42)/$Y42 -> #REF! | AI42: =(S42-$Y42)/$Y42 -> #REF! | ... AK42: =(U42-$Y42)/$Y42 -> #REF! | AM42: =SUM(AB42:AK42) -> #REF!
A43: CyberShake | B43: 50 | C43: 0.7 | D43: 203.32952 | E43: 2.89893 | F43: 233 | H43: Sipht | I43: 58 | J43: 1 | L43: =INDIRECT("D"&1+(ROW(D42)-1)*10+COLUMN(A42)-1) -> 1546.5742 | M43: =INDIRECT("D"&1+(ROW(E42)-1)*10+COLUMN(B42)-1) -> 1546.5742 | N43: =INDIRECT("D"&1+(ROW(F42)-1)*10+COLUMN(C42)-1) -> 1546.5742 | O43: =INDIRECT("D"&1+(ROW(G42)-1)*10+COLUMN(D42)-1) -> 1546.5742 | P43: =INDIRECT("D"&1+(ROW(H42)-1)*10+COLUMN(E42)-1) -> 1546.5742 | Q43: =INDIRECT("D"&1+(ROW(I42)-1)*10+COLUMN(F42)-1) -> 1546.5742 | R43: =INDIRECT("D"&1+(ROW(J42)-1)*10+COLUMN(G42)-1) -> 1546.5742 | S43: =INDIRECT("D"&1+(ROW(K42)-1)*10+COLUMN(H42)-1) -> 1546.5742 | ... U43: =INDIRECT("D"&1+(ROW(M42)-1)*10+COLUMN(J42)-1) -> 1546.5742 | W43: =AVERAGE(L43:U43) -> 1546.5742 | Y43: =Total!#REF! -> #REF! | AB43: =(L43-$Y43)/$Y43 -> #REF! | AC43: =(M43-$Y43)/$Y43 -> #REF! | AD43: =(N43-$Y43)/$Y43 -> #REF! | AE43: =(O43-$Y43)/$Y43 -> #REF! | AF43: =(P43-$Y43)/$Y43 -> #REF! | AG43: =(Q43-$Y43)/$Y43 -> #REF! | AH43: =(R43-$Y43)/$Y43 -> #REF! | AI43: =(S43-$Y43)/$Y43 -> #REF! | ... AK43: =(U43-$Y43)/$Y43 -> #REF! | AM43: =SUM(AB43:AK43) -> #REF!
A44: CyberShake | B44: 50 | C44: 0.7 | D44: 203.32952 | E44: 2.89721 | F44: 232 | H44: Sipht | I44: 97 | J44: 0.4 | L44: =INDIRECT("D"&1+(ROW(D43)-1)*10+COLUMN(A43)-1) -> 2521.7109 | M44: =INDIRECT("D"&1+(ROW(E43)-1)*10+COLUMN(B43)-1) -> 2521.7109 | N44: =INDIRECT("D"&1+(ROW(F43)-1)*10+COLUMN(C43)-1) -> 2521.7109 | O44: =INDIRECT("D"&1+(ROW(G43)-1)*10+COLUMN(D43)-1) -> 2521.7109 | P44: =INDIRECT("D"&1+(ROW(H43)-1)*10+COLUMN(E43)-1) -> 2521.7109 | Q44: =INDIRECT("D"&1+(ROW(I43)-1)*10+COLUMN(F43)-1) -> 2521.7109 | R44: =INDIRECT("D"&1+(ROW(J43)-1)*10+COLUMN(G43)-1) -> 2521.7109 | S44: =INDIRECT("D"&1+(ROW(K43)-1)*10+COLUMN(H43)-1) -> 2521.7109 | ... U44: =INDIRECT("D"&1+(ROW(M43)-1)*10+COLUMN(J43)-1) -> 2521.7109 | W44: =AVERAGE(L44:U44) -> 2521.7109 | Y44: =Total!#REF! -> #REF! | AB44: =(L44-$Y44)/$Y44 -> #REF! | AC44: =(M44-$Y44)/$Y44 -> #REF! | AD44: =(N44-$Y44)/$Y44 -> #REF! | AE44: =(O44-$Y44)/$Y44 -> #REF! | AF44: =(P44-$Y44)/$Y44 -> #REF! | AG44: =(Q44-$Y44)/$Y44 -> #REF! | AH44: =(R44-$Y44)/$Y44 -> #REF! | AI44: =(S44-$Y44)/$Y44 -> #REF! | ... AK44: =(U44-$Y44)/$Y44 -> #REF! | AM44: =SUM(AB44:AK44) -> #REF!
A45: CyberShake | B45: 50 | C45: 0.7 | D45: 203.32952 | E45: 2.88947 | F45: 240 | H45: Sipht | I45: 97 | J45: 0.7 | L45: =INDIRECT("D"&1+(ROW(D44)-1)*10+COLUMN(A44)-1) -> 2068.0264 | M45: =INDIRECT("D"&1+(ROW(E44)-1)*10+COLUMN(B44)-1) -> 2068.0264 | N45: =INDIRECT("D"&1+(ROW(F44)-1)*10+COLUMN(C44)-1) -> 2068.0264 | O45: =INDIRECT("D"&1+(ROW(G44)-1)*10+COLUMN(D44)-1) -> 2068.0264 | P45: =INDIRECT("D"&1+(ROW(H44)-1)*10+COLUMN(E44)-1) -> 2068.0264 | Q45: =INDIRECT("D"&1+(ROW(I44)-1)*10+COLUMN(F44)-1) -> 2068.0264 | R45: =INDIRECT("D"&1+(ROW(J44)-1)*10+COLUMN(G44)-1) -> 2068.0264 | S45: =INDIRECT("D"&1+(ROW(K44)-1)*10+COLUMN(H44)-1) -> 2068.0264 | ... U45: =INDIRECT("D"&1+(ROW(M44)-1)*10+COLUMN(J44)-1) -> 2068.0264 | W45: =AVERAGE(L45:U45) -> 2068.0264 | Y45: =Total!#REF! -> #REF! | AB45: =(L45-$Y45)/$Y45 -> #REF! | AC45: =(M45-$Y45)/$Y45 -> #REF! | AD45: =(N45-$Y45)/$Y45 -> #REF! | AE45: =(O45-$Y45)/$Y45 -> #REF! | AF45: =(P45-$Y45)/$Y45 -> #REF! | AG45: =(Q45-$Y45)/$Y45 -> #REF! | AH45: =(R45-$Y45)/$Y45 -> #REF! | AI45: =(S45-$Y45)/$Y45 -> #REF! | ... AK45: =(U45-$Y45)/$Y45 -> #REF! | AM45: =SUM(AB45:AK45) -> #REF!
